Workbook

Sheet Komparasi BM vs VM
A1: Baremetal | B1: Summary Hardware Baremetal
B2: No | C2: Group | D2: Description | E2: Edition | F2: Environment | G2: # of VM | H2: CPU | I2: Memory | J2: Storage | K2: Total CPU | L2: Total Memory | M2: Total Storage | N2: Pricing CPU | O2: Pricing Storage | P2: Pricing NBU | Q2: Pricing Baremetal | R2: Total
B3: 1 | C3: Redhat OCP Worker (Baremetal) | D3: Container Platform | E3: Enterprise | F3: DC1 | G3: 1 | H3: 64 | I3: 1024 | J3: 1024 | K3: =H3*G3 -> 64 | L3: =I3*G3 -> 1024 | M3: =J3*G3 -> 1024 | N3: 0 | O3: 0 | P3: 0 | Q3: =G3*#REF! -> #REF! | R3: =SUM(N3:Q3) -> #REF! | S3: Harga Baru
B4: 2 | C4: Redhat OCP Worker (Baremetal) | D4: Container Platform | E4: Enterprise | F4: DC2 | G4: 1 | H4: 64 | I4: 1024 | J4: 1024 | K4: =H4*G4 -> 64 | L4: =I4*G4 -> 1024 | M4: =J4*G4 -> 1024 | N4: 0 | O4: 0 | P4: 0 | Q4: =G4*#REF! -> #REF! | R4: =SUM(N4:Q4) -> #REF! | S4: Harga Baru
B6: 3 | C6: Redhat OCP Worker (Baremetal) | D6: Container Platform | E6: Enterprise | F6: PT | G6: 1 | H6: 64 | I6: 1024 | J6: 1024 | K6: =H6*G6 -> 64 | L6: =I6*G6 -> 1024 | M6: =J6*G6 -> 1024 | N6: 0 | O6: 0 | Q6: =G6*#REF! -> #REF! | R6: =SUM(N6:Q6) -> #REF! | S6: Harga Baru
B9: Summary Hardware Prod (Baremetal)
B10: No | C10: Item | D10: Price
B11: 1 | C11: Redhat OCP | D11: =SUM(R3:R3,R4:R4) -> #REF!
C12: Total | D12: =SUM(D11:D11) -> #REF!
B14: Summary Hardware PT (Baremetal)
B15: No | C15: Item | D15: Price
B16: 1 | C16: Redhat OCP | D16: =SUM(R6:R6) -> #REF!
C17: Total | D17: =SUM(D16:D16) -> #REF!
B20: Summary License Prod (Baremetal)
B21: No | C21: Item | D21: #of License | E21: Harga Satuan | F21: Total Harga | G21: Remarks
B22: 1 | C22: Redhat Openshift Kubernetes Engine (Baremetal) | D22: =G3+G4 -> 2 | E22: 236922840 | F22: =E22*D22 -> 473845680
C23: Total Harga | F23: =SUM(F22:F22) -> 473845680
B25: Summary License PT (Baremetal)
B26: No | C26: Item | D26: #of License | E26: Harga Satuan | F26: Total Harga | G26: Remarks
B27: 1 | C27: Redhat Openshift Kubernetes Engine (Baremetal) | D27: 1 | E27: 156369074 | F27: =E27*D27 -> 156369074
C28: Total Harga | F28: =SUM(F27:F27) -> 156369074
B31: Total Price Prod (Baremetal)
B32: No | C32: Item | D32: Total Harga
B33: 1 | C33: Hardware | D33: =D12 -> #REF!
B34: 2 | C34: License | D34: =F23 -> 473845680
C35: Total Harga | D35: =SUM(D33:D34) -> #REF!
B37: Total Price PT (Baremetal)
B38: No | C38: Item | D38: Total Harga
B39: 1 | C39: Hardware | D39: =D17 -> #REF!
B40: 2 | C40: License | D40: =F28 -> 156369074
C41: Total Harga | D41: =SUM(D39:D40) -> #REF!
A43: VM | B43: Summary Hardware VM
B44: No | C44: Group | D44: Description | E44: Edition | F44: Environment | G44: # of VM | H44: CPU | I44: Memory | J44: Storage | K44: Total CPU | L44: Total Memory | M44: Total Storage | N44: Pricing CPU | O44: Pricing Storage | P44: Pricing NBU | Q44: Pricing Baremetal | R44: Total
B45: 1 | C45: Redhat OCP Worker (VM) | D45: Container Platform | E45: Enterprise | F45: DC1 | G45: 16 | H45: 8 | I45: 16 | J45: 300 | K45: =H45*G45 -> 128 | L45: =I45*G45 -> 256 | M45: =J45*G45 -> 4800 | N45: =K45*#REF! -> #REF! | O45: =M45*#REF! -> #REF! | P45: 0 | Q45: 0 | R45: =SUM(N45:Q45) -> #REF!
B46: 2 | C46: Redhat OCP Worker (VM) | D46: Container Platform | E46: Enterprise | F46: DC2 | G46: 16 | H46: 8 | I46: 16 | J46: 300 | K46: =H46*G46 -> 128 | L46: =I46*G46 -> 256 | M46: =J46*G46 -> 4800 | N46: =K46*#REF! -> #REF! | O46: =M46*#REF! -> #REF! | P46: 0 | Q46: 0 | R46: =SUM(N46:Q46) -> #REF!
B48: 3 | C48: Redhat OCP Worker (VM) | D48: Container Platform | E48: Enterprise | F48: PT | G48: 16 | H48: 8 | I48: 16 | J48: 300 | K48: =H48*G48 -> 128 | L48: =I48*G48 -> 256 | M48: =J48*G48 -> 4800 | N48: =K48*#REF! -> #REF! | O48: =M48*#REF! -> #REF! | P48: 0 | Q48: 0 | R48: =SUM(N48:Q48) -> #REF!
B51: Summary Hardware Prod (VM)
B52: No | C52: Item | D52: Price
B53: 1 | C53: Redhat OCP | D53: =SUM(R45:R45,R46:R46) -> #REF!
C54: Total | D54: =SUM(D53:D53) -> #REF!
...

Sheet Pricing Per Items - old
C2: Prod dan PT | F2: Dev
C3: vCPU VM | D3: 7500000 | F3: vCPU VM | G3: =G4+G5 -> 6500000
C4: Per vCPU | D4: 5000000 | F4: Per vCPU | G4: 4000000
C5: NSX | D5: 2500000 | F5: NSX | G5: 2500000
C7: Memory | D7: 35000 | F7: Memory | G7: 24000
C9: Storage per GB | D9: 28800 | F9: Storage per GB | G9: 17900
C10: Rubrik | D10: 35000
C11: NBU | D11: 27000 | E11: =D11+D12 -> 88000
C12: VTL | D12: 61000
C14: Prod | F14: Dev PT | I14: Prod, Dev, PT
C15: Baremetal (License) | D15: 238000000 | F15: Baremetal (License) | G15: 141000000 | I15: Hardware Baremetal (HW) | J15: =275000000*112/111 -> 2.7747748e+08
C16: OKE | D16: 210500000
C18: Prod, PT, Dev
C19: vCPU DB (Oracle) | D19: 5266000
C20: Per vCPU | D20: 5000000
C21: OLVM | D21: 266000 | G21: 2.4773958e+09
G22: 64
C24: Windows Server | F24: Harga License Oracle per core | G24: =G21/G22 -> 38709309
C25: Standard | D25: =1888000 -> 1888000
C26: Enterprise | D26: 11345455
E27: =112%*10400000 -> 11648000
F28: OCP VM License | G28: DC1 | I28: 48972000
C29: SQL Server | F29: OCP VM License | G29: DC2 | I29: 48972000
C30: Standard | D30: 48880000 | F30: OCP VM License | G30: PreProd | I30: 48972000
C31: Enterprise | D31: 187200000 | F31: OCP VM License | G31: NPD | I31: 33056000
H32: =12*I31 -> 396672000
C33: Redis | D33: 1.2924982e+08 | E33: =70909280*112/111 -> 71548102
C35: Kafka | D35: 151447620 | E35: =69413760*112/111 -> 70039109
C37: Elasticsearch | D37: 1.1954727e+08
C39: Mongo DB | D39: 298000000
C41: RHEL | D41: 48000000
C42: Windows Server 2022 | D42: 11345455
C44: Secure Site Pro EV SSL | D44: 25262182
C47: License Appdynamic - AppD Peak Ed - APM Any Language Microservice (5-pack) - On-Prem | D47: 8392363.6
C49: Baremetal (64 Core) | D49: 284828000 | E49: Baremetal (96 Core) | F49: =477000000*112/111 -> 4.812973e+08
C51: NGINX Prod | D51: 1.0640073e+08
C52: NGINX Preprod (SIT, UAT) | D52: 49206000
C54: Oracle Database Enterprise Edition | D54: 2.6362411e+08
C55: Oracle Diagnostic Pack | D55: 41624860
C56: Oracle Partitioning | D56: 63824785
...

Sheet Pricing Per Items - old adj
C2: Prod dan PT | F2: Dev
C3: vCPU VM | D3: 7500000 | F3: vCPU VM | G3: =G4+G5 -> 6500000
C4: Per vCPU | D4: 5000000 | F4: Per vCPU | G4: 4000000
C5: NSX | D5: 2500000 | F5: NSX | G5: 2500000
C7: Memory | D7: 35000 | F7: Memory | G7: 24000
C9: Storage per GB | D9: 24500 | F9: Storage per GB | G9: 16000
C10: Rubrik | D10: 35000
C11: NBU | D11: 27000 | E11: =D11+D12 -> 88000
C12: VTL | D12: 61000
C14: Prod | F14: Dev PT | I14: Prod, Dev, PT
C15: Baremetal | D15: 238000000 | F15: Baremetal | G15: 145000000 | I15: Hardware Baremetal (HW) | J15: =275000000*112/111 -> 2.7747748e+08
C16: OPP | D16: 210000000
C17: OKE | D17: 203280000
C18: Prod, PT, Dev
C19: vCPU DB (Oracle) | D19: 5266000
C20: Per vCPU | D20: 5000000
C21: OLVM | D21: 266000 | G21: 2.4773958e+09
G22: 64
C24: Windows Server | F24: Harga License Oracle per core | G24: =G21/G22 -> 38709309
C25: Standard | D25: =1888000 -> 1888000
C26: Enterprise | D26: 11345455
E27: =112%*10400000 -> 11648000
F28: OCP VM License | G28: DC1 | I28: 48972000
C29: SQL Server | F29: OCP VM License | G29: DC2 | I29: 48972000
C30: Standard | D30: 48880000 | F30: OCP VM License | G30: PreProd | I30: 48972000
C31: Enterprise | D31: 187200000 | F31: OCP VM License | G31: NPD | I31: 33056000
H32: =12*I31 -> 396672000
C33: Redis | D33: 1.2924982e+08 | E33: =70909280*112/111 -> 71548102
C35: Kafka | D35: 151447620 | E35: =69413760*112/111 -> 70039109
C37: Elasticsearch | D37: 1.1954727e+08
C39: Mongo DB | D39: 298000000
C41: RHEL | D41: 47423000
C43: Secure Site Pro EV SSL | D43: 25262182
C46: License Appdynamic - AppD Peak Ed - APM Any Language Microservice (5-pack) - On-Prem | D46: 8392363.6
C48: Baremetal (64 Core) | D48: 284828000 | E48: Baremetal (96 Core) | F48: =500850000 -> 500850000
C50: NGINX Prod | D50: 1.0640073e+08
C51: NGINX Preprod (SIT, UAT) | D51: 49206000
C53: Oracle Database Enterprise Edition | D53: 2.6362411e+08
C54: Oracle Diagnostic Pack | D54: 41624860
C55: Oracle Partitioning | D55: 63824785
...

Sheet Pricing
A1: Hardware
A2: No | B2: Item | C2: Env | D2: Price
A3: 1 | B3: vCPU | C3: Production | D3: =7500000*110% -> 8250000
A4: 2 | B4: vCPU | C4: Dev | D4: =6500000*110% -> 7150000
A5: 3 | B5: Storage Tier 2 | C5: Production | D5: 33000
A6: 4 | B6: Storage Tier 3 | C6: Production | D6: 48000
A7: 5 | B7: Storage Dev | C7: Dev | D7: 28600
A8: 6 | B8: Netbackup | C8: Production | D8: 27000
A9: 7 | B9: Rubrik | C9: Production | D9: 35000
A10: 8 | B10: Baremetal | C10: Production | D10: 794000000
A11: 9 | B11: Baremetal | C11: Dev | D11: 794000000
A14: License
A15: No | B15: Item | C15: Env | D15: Price
A16: 1 | B16: NGINX | C16: Production
A17: 2 | B17: NGINX | C17: Dev
A18: 3 | B18: Openshift | C18: Production | D18: 240000000
A19: 4 | B19: Openshift | C19: Dev | D19: 134000000
A20: 5 | B20: Redis | C20: Production | D20: 125000000
A21: 6 | B21: Redis | C21: Dev | D21: 75000000
A22: 7 | B22: Confluent Kafka | C22: Production
A23: 8 | B23: Confluent Kafka | C23: Dev
A24: Note : Perlu confirm ke STA, untuk harga terbaru

Sheet Sheet1
C2: Hardware
C3: License | D3: License type | E3: price type | F3: Pricing
C4: VM Prod | D4: CPU | E4: per vcpu | F4: 5000000
D5: Storage | E5: per GB | F5: 24500
C6: VM Prod | D6: CPU | E6: per vcpu | F6: 5000000
D7: Storage | E7: per GB | F7: 24500
C8: Baremetal | D8: Socket | E8: 2 Socket (upto 64 Core) | F8: 238000000
C10: Backup (Production)
C11: License | D11: License type | E11: price type | F11: Pricing
C12: Netbackup | D12: Storage | E12: Per GB | F12: 27000
C14: OS
C15: License | D15: License type | E15: price type | F15: Pricing
C16: Windows Server Datacenter | D16: Perpetual | E16: 2 Physical Core | F16: 12000000
C17: Linux Rhel | D17: Subcription | E17: per Host | F17: 17700000
C18: Oracle Linux | D18: Subcription | E18: per Host / 2 socket | F18: 24000000
C22: Platform (Production) | H22: Platform (Non Production)
C23: License | D23: License type | E23: price type | F23: Pricing | H23: License | I23: License type | J23: price type | K23: Pricing
C24: Nginx Plus | D24: Subcription | E24: per Node | F24: 106400727 | H24: Nginx Plus | I24: Subcription | J24: per Node | K24: 49206000
C25: Redis | D25: Subcription | E25: per Shards (Max 25 GB Memory Usage / 12500 ops / sec) | F25: 129249818 | H25: Redis | I25: Subcription | J25: per Shards (Max 25 GB Memory Usage / 12500 ops / sec) | K25: 71548102
C26: Confluent Kafka | D26: Subcription | E26: per Node (Broker, Zookeeper, C3) | F26: 151447620 | H26: Confluent Kafka | I26: Subcription | J26: per Node (Broker, Zookeeper, C3) | K26: 70039109
C27: Elasticsearch | D27: Subcription | E27: per Node (Master, Coord, Data, Hot, Warm, Cold) Max 16 Core per Node | F27: 119547273 | H27: Elasticsearch | I27: Subcription | J27: per Node (Master, Coord, Data, Hot, Warm, Cold) Max 16 Core per Node | K27: 0
C28: Redhat OCP Baremetal OKE | D28: Subcription | E28: per Host / 2 Socket | F28: 203280000 | H28: Redhat OCP Baremetal OKE | I28: Subcription | J28: per Host / 2 Socket | K28: 134164800
C30: Others
C31: License | D31: License type | E31: price type | F31: Pricing
C32: Secure Site OV (dev public) | D32: Subcription | E32: per SSL | F32: 6767904
C33: Secure Site Pro EV SSL (Prod public with trx) | D33: Subcription | E33: per SSL | F33: 23868000
C34: Secure Site Pro SSL (Prod public w/o trx) | D34: Subcription | E34: per SSL | F34: 16866720
C35: Secure Site Wildcard | D35: Subcription | E35: per SSL | F35: 33945600
C36: GuardSquare DexGuard | D36: Subcription | E36: up to 50K Download | F36: 525600000
C37: GuardSquare iXGuard | D37: Subcription | E37: up to 50K Download | F37: 525600000
C38: JSL Guardquare | D38: JSL | E38: 1 Dedicated Junior 12 Months | F38: 198000000
C40: Database
C41: License | D41: License type | E41: price type | F41: Pricing
C42: Oracle Database Enterprise Edition | D42: Subcription | E42: Total Core * 0,5 | F42: 2.6362411e+08
C43: Oracle Diagnostic Pack | D43: Subcription | E43: Total Core * 0,5 | F43: 41624860
C44: Oracle Partitioning | D44: Subcription | E44: Total Core * 0,5 | F44: 63824785
C45: Oracle Tuning Pack | D45: Subcription | E45: Total Core * 0,5 | F45: 27749906
C46: Oracle Real Application Cluster | D46: Subcription | E46: Total Core * 0,5 | F46: 1.2764957e+08
C47: Oracle Active Data Guard | D47: Subcription | E47: Total Core * 0,5 | F47: 63824785
C48: SQL Server 2019 | D48: Perpetual | E48: Per 2 Physical Core | F48: 187200000

Sheet Opsi Oracle
B1: Summary Hardware
B2: No | C2: Group | D2: Description | E2: Edition | F2: Environment | G2: # of VM | H2: CPU | I2: Memory | J2: Storage | K2: Total CPU | L2: Total Memory | M2: Total Storage | N2: Pricing CPU | O2: Pricing Storage | P2: Pricing Rubrik / NBU | Q2: Pricing Baremetal | R2: Total
B3: 1 | C3: Redhat OCP Master | D3: Container Platform | E3: Enterprise | F3: DC1 | G3: 3 | H3: 8 | I3: 32 | J3: 150 | K3: =H3*G3 -> 24 | L3: =I3*G3 -> 96 | M3: =J3*G3 -> 450 | N3: =K3*#REF! -> #REF! | O3: =M3*#REF! -> #REF! | P3: 0 | R3: =SUM(N3:Q3) -> #REF!
B4: 2 | C4: Redhat OCP Infra Router | D4: Container Platform | E4: Enterprise | F4: DC1 | G4: 5 | H4: 8 | I4: 32 | J4: 150 | K4: =H4*G4 -> 40 | L4: =I4*G4 -> 160 | M4: =J4*G4 -> 750 | N4: =K4*#REF! -> #REF! | O4: =M4*#REF! -> #REF! | P4: 0 | R4: =SUM(N4:Q4) -> #REF!
B5: 3 | C5: Redhat OCP Worker (Baremetal) | D5: Container Platform | E5: Enterprise | F5: DC1 | G5: 1 | H5: 64 | I5: 1024 | J5: 1024 | K5: =H5*G5 -> 64 | L5: =I5*G5 -> 1024 | M5: =J5*G5 -> 1024 | N5: 0 | O5: 0 | P5: 0 | Q5: =G5*#REF! -> #REF! | R5: =SUM(N5:Q5) -> #REF! | S5: Harga Baru
B6: 4 | C6: Bastion & HA Proxy | D6: Bastion | E6: Enterprise | F6: DC1 | G6: 1 | H6: 4 | I6: 8 | J6: 100 | K6: =H6*G6 -> 4 | L6: =I6*G6 -> 8 | M6: =J6*G6 -> 100 | N6: =K6*#REF! -> #REF! | O6: =M6*#REF! -> #REF! | P6: 0 | R6: =SUM(N6:Q6) -> #REF!
B7: 5 | C7: Oracle Database RAC (Baremetal) | D7: Database | E7: Enterprise | F7: DC1 | G7: 2 | H7: 64 | I7: 1024 | J7: 2500 | K7: =H7*G7 -> 128 | L7: =I7*G7 -> 2048 | M7: =J7 -> 2500 | N7: 0 | O7: =M7*#REF! -> #REF! | P7: =M7*#REF!*50% -> #REF! | Q7: =G7*#REF! -> #REF! | R7: =SUM(N7:Q7) -> #REF! | S7: Harga PO
B8: 6 | C8: Nginx Community | D8: Application Gateway | E8: Community | F8: DC1 | G8: 2 | H8: 8 | I8: 16 | J8: 200 | K8: =H8*G8 -> 16 | L8: =I8*G8 -> 32 | M8: =G8*J8 -> 400 | N8: =K8*#REF! -> #REF! | O8: =M8*#REF! -> #REF! | R8: =SUM(N8:Q8) -> #REF!
B9: 7 | C9: Redis Enterprise | D9: Cache Database | E9: Enterprise | F9: DC1 | G9: 3 | H9: 8 | I9: 16 | J9: 200 | K9: =H9*G9 -> 24 | L9: =I9*G9 -> 48 | M9: =G9*J9 -> 600 | N9: =K9*#REF! -> #REF! | O9: =M9*#REF! -> #REF! | R9: =SUM(N9:Q9) -> #REF!
B10: 8 | C10: Confluent Kafka Community App Log (Non Financial) | D10: Kafka Broker & Zookeeper | E10: Community | F10: DC1 | G10: 3 | H10: 8 | I10: 16 | J10: 1000 | K10: =H10*G10 -> 24 | L10: =I10*G10 -> 48 | M10: =G10*J10 -> 3000 | N10: =K10*#REF! -> #REF! | O10: =M10*#REF! -> #REF! | R10: =SUM(N10:Q10) -> #REF!
B11: 9 | C11: Batch Control M | D11: Batch Server | E11: Enterprise | F11: DC1 | G11: 1 | H11: 8 | I11: 16 | J11: 500 | K11: =H11*G11 -> 8 | L11: =I11*G11 -> 16 | M11: =G11*J11 -> 500 | N11: =K11*#REF! -> #REF! | O11: =M11*#REF! -> #REF! | R11: =SUM(N11:Q11) -> #REF!
B12: 10 | C12: MinIO | D12: Object Storage | E12: Community | F12: DC1 | G12: 1 | H12: 16 | I12: 32 | J12: 500 | K12: =H12*G12 -> 16 | L12: =I12*G12 -> 32 | M12: =G12*J12 -> 500 | N12: =K12*#REF! -> #REF! | O12: =M12*#REF! -> #REF! | R12: =SUM(N12:Q12) -> #REF!
B13: 11 | C13: Elasticsearch Master & Data | D13: ELK Stack | E13: Community | F13: DC1 | G13: 3 | H13: 8 | I13: 32 | J13: 300 | K13: =H13*G13 -> 24 | L13: =I13*G13 -> 96 | M13: =G13*J13 -> 900 | N13: =K13*#REF! -> #REF! | O13: =M13*#REF! -> #REF! | R13: =SUM(N13:Q13) -> #REF!
B14: 12 | C14: Kibana Logstash | D14: ELK Stack | E14: Community | F14: DC1 | G14: 1 | H14: 8 | I14: 16 | J14: 300 | K14: =H14*G14 -> 8 | L14: =I14*G14 -> 16 | M14: =G14*J14 -> 300 | N14: =K14*#REF! -> #REF! | O14: =M14*#REF! -> #REF! | R14: =SUM(N14:Q14) -> #REF!
B15: 13 | C15: Redhat OCP Master | D15: Container Platform | E15: Enterprise | F15: DC2 | G15: 3 | H15: 8 | I15: 32 | J15: 150 | K15: =H15*G15 -> 24 | L15: =I15*G15 -> 96 | M15: =J15*G15 -> 450 | N15: =K15*#REF! -> #REF! | O15: =M15*#REF! -> #REF! | P15: 0 | R15: =SUM(N15:Q15) -> #REF!
B16: 14 | C16: Redhat OCP Infra Router | D16: Container Platform | E16: Enterprise | F16: DC2 | G16: 5 | H16: 8 | I16: 32 | J16: 150 | K16: =H16*G16 -> 40 | L16: =I16*G16 -> 160 | M16: =J16*G16 -> 750 | N16: =K16*#REF! -> #REF! | O16: =M16*#REF! -> #REF! | P16: 0 | R16: =SUM(N16:Q16) -> #REF!
B17: 15 | C17: Redhat OCP Worker (Baremetal) | D17: Container Platform | E17: Enterprise | F17: DC2 | G17: 1 | H17: 64 | I17: 1024 | J17: 1024 | K17: =H17*G17 -> 64 | L17: =I17*G17 -> 1024 | M17: =J17*G17 -> 1024 | N17: 0 | O17: 0 | P17: 0 | Q17: =G17*#REF! -> #REF! | R17: =SUM(N17:Q17) -> #REF! | S17: Harga Baru
B18: 16 | C18: Bastion & HA Proxy | D18: Bastion | E18: Enterprise | F18: DC2 | G18: 1 | H18: 4 | I18: 8 | J18: 100 | K18: =H18*G18 -> 4 | L18: =I18*G18 -> 8 | M18: =J18*G18 -> 100 | N18: =K18*#REF! -> #REF! | O18: =M18*#REF! -> #REF! | P18: 0 | R18: =SUM(N18:Q18) -> #REF!
B19: 17 | C19: Oracle Database RAC (Baremetal) | D19: Database | E19: Enterprise | F19: DC2 | G19: 2 | H19: 64 | I19: 1024 | J19: 2500 | K19: =H19*G19 -> 128 | L19: =I19*G19 -> 2048 | M19: =J19 -> 2500 | N19: 0 | O19: =M19*#REF! -> #REF! | P19: =M19*#REF!*50% -> #REF! | Q19: =G19*#REF! -> #REF! | R19: =SUM(N19:Q19) -> #REF! | S19: Harga PO
B20: 18 | C20: Nginx Community | D20: Application Gateway | E20: Community | F20: DC2 | G20: 2 | H20: 8 | I20: 16 | J20: 200 | K20: =H20*G20 -> 16 | L20: =I20*G20 -> 32 | M20: =J20*G20 -> 400 | N20: =K20*#REF! -> #REF! | O20: =M20*#REF! -> #REF! | R20: =SUM(N20:Q20) -> #REF!
B21: 19 | C21: Redis Enterprise | D21: Cache Database | E21: Enterprise | F21: DC2 | G21: 3 | H21: 8 | I21: 16 | J21: 200 | K21: =H21*G21 -> 24 | L21: =I21*G21 -> 48 | M21: =J21*G21 -> 600 | N21: =K21*#REF! -> #REF! | O21: =M21*#REF! -> #REF! | R21: =SUM(N21:Q21) -> #REF!
B22: 20 | C22: Confluent Kafka Community App Log (Non Financial) | D22: Kafka Broker & Zookeeper | E22: Community | F22: DC2 | G22: 3 | H22: 8 | I22: 16 | J22: 1000 | K22: =H22*G22 -> 24 | L22: =I22*G22 -> 48 | M22: =J22*G22 -> 3000 | N22: =K22*#REF! -> #REF! | O22: =M22*#REF! -> #REF! | R22: =SUM(N22:Q22) -> #REF!
B23: 21 | C23: Batch Control M | D23: Batch Server | E23: Enterprise | F23: DC2 | G23: 1 | H23: 8 | I23: 16 | J23: 500 | K23: =H23*G23 -> 8 | L23: =I23*G23 -> 16 | M23: =J23*G23 -> 500 | N23: =K23*#REF! -> #REF! | O23: =M23*#REF! -> #REF! | R23: =SUM(N23:Q23) -> #REF!
B24: 22 | C24: MinIO | D24: Object Storage | E24: Community | F24: DC2 | G24: 1 | H24: 16 | I24: 32 | J24: 500 | K24: =H24*G24 -> 16 | L24: =I24*G24 -> 32 | M24: =J24*G24 -> 500 | N24: =K24*#REF! -> #REF! | O24: =M24*#REF! -> #REF! | R24: =SUM(N24:Q24) -> #REF!
B25: 23 | C25: Elasticsearch Master & Data | D25: ELK Stack | E25: Community | F25: DC2 | G25: 3 | H25: 8 | I25: 32 | J25: 300 | K25: =H25*G25 -> 24 | L25: =I25*G25 -> 96 | M25: =J25*G25 -> 900 | N25: =K25*#REF! -> #REF! | O25: =M25*#REF! -> #REF! | R25: =SUM(N25:Q25) -> #REF! | T25: VM | U25: 15 TB
B26: 24 | C26: Kibana Logstash | D26: ELK Stack | E26: Community | F26: DC2 | G26: 1 | H26: 8 | I26: 16 | J26: 300 | K26: =H26*G26 -> 8 | L26: =I26*G26 -> 16 | M26: =J26*G26 -> 300 | N26: =K26*#REF! -> #REF! | O26: =M26*#REF! -> #REF! | R26: =SUM(N26:Q26) -> #REF!
B28: 25 | C28: Redhat OCP Master | D28: Container Platform | E28: Enterprise | F28: PT | G28: 3 | H28: 8 | I28: 32 | J28: 150 | K28: =H28*G28 -> 24 | L28: =I28*G28 -> 96 | M28: =J28*G28 -> 450 | N28: =K28*#REF! -> #REF! | O28: =M28*#REF! -> #REF! | R28: =SUM(N28:Q28) -> #REF!
B29: 26 | C29: Redhat OCP Infra Router | D29: Container Platform | E29: Enterprise | F29: PT | G29: 5 | H29: 8 | I29: 32 | J29: 150 | K29: =H29*G29 -> 40 | L29: =I29*G29 -> 160 | M29: =J29*G29 -> 750 | N29: =K29*#REF! -> #REF! | O29: =M29*#REF! -> #REF! | R29: =SUM(N29:Q29) -> #REF!
B30: 27 | C30: Redhat OCP Worker (Baremetal) | D30: Container Platform | E30: Enterprise | F30: PT | G30: 1 | H30: 64 | I30: 1024 | J30: 1024 | K30: =H30*G30 -> 64 | L30: =I30*G30 -> 1024 | M30: =J30*G30 -> 1024 | N30: 0 | O30: 0 | Q30: =G30*#REF! -> #REF! | R30: =SUM(N30:Q30) -> #REF! | S30: Harga Baru
B31: 28 | C31: Bastion & HA Proxy | D31: Bastion | E31: Enterprise | F31: PT | G31: 1 | H31: 4 | I31: 8 | J31: 100 | K31: =H31*G31 -> 4 | L31: =I31*G31 -> 8 | M31: =J31*G31 -> 100 | N31: =K31*#REF! -> #REF! | O31: =M31*#REF! -> #REF! | R31: =SUM(N31:Q31) -> #REF!
B32: 29 | C32: Oracle Database RAC (Baremetal) | D32: Database | E32: Enterprise | F32: PT | G32: 2 | H32: 64 | I32: 1024 | J32: 2500 | K32: =H32*G32 -> 128 | L32: =I32*G32 -> 2048 | M32: =J32 -> 2500 | N32: 0 | O32: =M32*#REF! -> #REF! | Q32: =G32*#REF! -> #REF! | R32: =SUM(N32:Q32) -> #REF! | S32: Harga Baru
B33: 30 | C33: Nginx Community | D33: Application Gateway | E33: Community | F33: PT | G33: 2 | H33: 8 | I33: 16 | J33: 200 | K33: =H33*G33 -> 16 | L33: =I33*G33 -> 32 | M33: =J33*G33 -> 400 | N33: =K33*#REF! -> #REF! | O33: =M33*#REF! -> #REF! | R33: =SUM(N33:Q33) -> #REF!
B34: 31 | C34: Redis Enterprise | D34: Cache Database | E34: Enterprise | F34: PT | G34: 3 | H34: 8 | I34: 16 | J34: 200 | K34: =H34*G34 -> 24 | L34: =I34*G34 -> 48 | M34: =J34*G34 -> 600 | N34: =K34*#REF! -> #REF! | O34: =M34*#REF! -> #REF! | R34: =SUM(N34:Q34) -> #REF!
B35: 32 | C35: Confluent Kafka Community App Log (Non Financial) | D35: Kafka Broker & Zookeeper | E35: Community | F35: PT | G35: 3 | H35: 8 | I35: 16 | J35: 1000 | K35: =H35*G35 -> 24 | L35: =I35*G35 -> 48 | M35: =J35*G35 -> 3000 | N35: =K35*#REF! -> #REF! | O35: =M35*#REF! -> #REF! | R35: =SUM(N35:Q35) -> #REF!
B36: 33 | C36: Batch Control M | D36: Batch Server | E36: Enterprise | F36: PT | G36: 1 | H36: 8 | I36: 16 | J36: 500 | K36: =H36*G36 -> 8 | L36: =I36*G36 -> 16 | M36: =J36*G36 -> 500 | N36: =K36*#REF! -> #REF! | O36: =M36*#REF! -> #REF! | R36: =SUM(N36:Q36) -> #REF!
B37: 34 | C37: MinIO | D37: Object Storage | E37: Enterprise | F37: PT | G37: 1 | H37: 16 | I37: 32 | J37: 500 | K37: =H37*G37 -> 16 | L37: =I37*G37 -> 32 | M37: =J37*G37 -> 500 | N37: =K37*#REF! -> #REF! | O37: =M37*#REF! -> #REF! | R37: =SUM(N37:Q37) -> #REF!
B38: 35 | C38: Elasticsearch Master & Data | D38: ELK Stack | E38: Community | F38: PT | G38: 3 | H38: 8 | I38: 32 | J38: 300 | K38: =H38*G38 -> 24 | L38: =I38*G38 -> 96 | M38: =J38*G38 -> 900 | N38: =K38*#REF! -> #REF! | O38: =M38*#REF! -> #REF! | R38: =SUM(N38:Q38) -> #REF!
B39: 36 | C39: Kibana Logstash | D39: ELK Stack | E39: Community | F39: PT | G39: 1 | H39: 8 | I39: 16 | J39: 300 | K39: =H39*G39 -> 8 | L39: =I39*G39 -> 16 | M39: =J39*G39 -> 300 | N39: =K39*#REF! -> #REF! | O39: =M39*#REF! -> #REF! | R39: =SUM(N39:Q39) -> #REF!
B40: 37 | C40: Wiremock | D40: Wiremock | E40: Community | F40: PT | G40: 2 | H40: 8 | I40: 24 | J40: 128 | K40: =H40*G40 -> 16 | L40: =I40*G40 -> 48 | M40: =J40*G40 -> 256 | N40: =K40*#REF! -> #REF! | O40: =M40*#REF! -> #REF! | R40: =SUM(N40:Q40) -> #REF!
B42: 38 | C42: Oracle Database (VM) | D42: Database | E42: Enterprise | F42: DEV & UAT | G42: 1 | H42: 16 | I42: 32 | J42: 500 | K42: =H42*G42 -> 16 | L42: =I42*G42 -> 32 | M42: =J42*G42 -> 500 | N42: =K42*#REF! -> #REF! | O42: =M42*#REF! -> #REF! | R42: =SUM(N42:Q42) -> #REF!
...

Sheet FS Opsi Oracle 20260515
B1: Summary Hardware
B2: No | C2: Group | D2: Description | E2: Edition | F2: Environment | G2: # of VM | H2: CPU | I2: Memory | J2: Storage | K2: Total CPU | L2: Total Memory | M2: Total Storage | N2: Pricing CPU | O2: Pricing Storage | P2: Pricing Rubrik / NBU | Q2: Pricing Baremetal | R2: Total
B3: 1 | C3: Redhat OCP Master | D3: Container Platform | E3: Enterprise | F3: DC1 | G3: 3 | H3: 8 | I3: 32 | J3: 150 | K3: =H3*G3 -> 24 | L3: =I3*G3 -> 96 | M3: =J3*G3 -> 450 | N3: =K3*#REF! -> #REF! | O3: =M3*#REF! -> #REF! | P3: 0 | R3: =SUM(N3:Q3) -> #REF!
B4: 2 | C4: Redhat OCP Infra Router | D4: Container Platform | E4: Enterprise | F4: DC1 | G4: 5 | H4: 8 | I4: 32 | J4: 150 | K4: =H4*G4 -> 40 | L4: =I4*G4 -> 160 | M4: =J4*G4 -> 750 | N4: =K4*#REF! -> #REF! | O4: =M4*#REF! -> #REF! | P4: 0 | R4: =SUM(N4:Q4) -> #REF!
B5: 3 | C5: Redhat OCP Worker (Baremetal) | D5: Container Platform | E5: Enterprise | F5: DC1 | G5: 1 | H5: 64 | I5: 1024 | J5: 1024 | K5: =H5*G5 -> 64 | L5: =I5*G5 -> 1024 | M5: =J5*G5 -> 1024 | N5: 0 | O5: 0 | P5: 0 | Q5: =G5*#REF! -> #REF! | R5: =SUM(N5:Q5) -> #REF!
B6: 4 | C6: Bastion & HA Proxy | D6: Bastion | E6: Enterprise | F6: DC1 | G6: 1 | H6: 4 | I6: 8 | J6: 100 | K6: =H6*G6 -> 4 | L6: =I6*G6 -> 8 | M6: =J6*G6 -> 100 | N6: =K6*#REF! -> #REF! | O6: =M6*#REF! -> #REF! | P6: 0 | R6: =SUM(N6:Q6) -> #REF!
B7: 5 | C7: Oracle Database RAC (Baremetal) | D7: Database | E7: Enterprise | F7: DC1 | G7: 2 | H7: 64 | I7: 1024 | J7: 423000 | K7: =H7*G7 -> 128 | L7: =I7*G7 -> 2048 | M7: =J7 -> 423000 | N7: 0 | O7: =M7*#REF! -> #REF! | P7: =M7*50%*80%*#REF! -> #REF! | Q7: =G7*#REF! -> #REF! | R7: =SUM(N7:Q7) -> #REF!
B8: 6 | C8: Nginx Community | D8: Application Gateway | E8: Community | F8: DC1 | G8: 2 | H8: 8 | I8: 16 | J8: 200 | K8: =H8*G8 -> 16 | L8: =I8*G8 -> 32 | M8: =G8*J8 -> 400 | N8: =K8*#REF! -> #REF! | O8: =M8*#REF! -> #REF! | R8: =SUM(N8:Q8) -> #REF!
B9: 7 | C9: Redis Enterprise | D9: Cache Database | E9: Enterprise | F9: DC1 | G9: 3 | H9: 8 | I9: 16 | J9: 200 | K9: =H9*G9 -> 24 | L9: =I9*G9 -> 48 | M9: =G9*J9 -> 600 | N9: =K9*#REF! -> #REF! | O9: =M9*#REF! -> #REF! | R9: =SUM(N9:Q9) -> #REF!
B10: 8 | C10: Confluent Kafka Community App Log (Non Financial) | D10: Kafka Broker & Zookeeper | E10: Community | F10: DC1 | G10: 3 | H10: 8 | I10: 16 | J10: 1000 | K10: =H10*G10 -> 24 | L10: =I10*G10 -> 48 | M10: =G10*J10 -> 3000 | N10: =K10*#REF! -> #REF! | O10: =M10*#REF! -> #REF! | R10: =SUM(N10:Q10) -> #REF!
B11: 9 | C11: Batch Control M | D11: Batch Server | E11: Enterprise | F11: DC1 | G11: 1 | H11: 8 | I11: 16 | J11: 500 | K11: =H11*G11 -> 8 | L11: =I11*G11 -> 16 | M11: =G11*J11 -> 500 | N11: =K11*#REF! -> #REF! | O11: =M11*#REF! -> #REF! | R11: =SUM(N11:Q11) -> #REF!
B12: 10 | C12: MinIO | D12: Object Storage | E12: Community | F12: DC1 | G12: 1 | H12: 16 | I12: 32 | J12: 500 | K12: =H12*G12 -> 16 | L12: =I12*G12 -> 32 | M12: =G12*J12 -> 500 | N12: =K12*#REF! -> #REF! | O12: =M12*#REF! -> #REF! | R12: =SUM(N12:Q12) -> #REF!
B13: 11 | C13: Elasticsearch Master & Data | D13: ELK Stack | E13: Community | F13: DC1 | G13: 3 | H13: 8 | I13: 32 | J13: 300 | K13: =H13*G13 -> 24 | L13: =I13*G13 -> 96 | M13: =G13*J13 -> 900 | N13: =K13*#REF! -> #REF! | O13: =M13*#REF! -> #REF! | R13: =SUM(N13:Q13) -> #REF!
B14: 12 | C14: Kibana Logstash | D14: ELK Stack | E14: Community | F14: DC1 | G14: 1 | H14: 8 | I14: 16 | J14: 300 | K14: =H14*G14 -> 8 | L14: =I14*G14 -> 16 | M14: =G14*J14 -> 300 | N14: =K14*#REF! -> #REF! | O14: =M14*#REF! -> #REF! | R14: =SUM(N14:Q14) -> #REF!
B15: 13 | C15: Redhat OCP Master | D15: Container Platform | E15: Enterprise | F15: DC2 | G15: 3 | H15: 8 | I15: 32 | J15: 150 | K15: =H15*G15 -> 24 | L15: =I15*G15 -> 96 | M15: =J15*G15 -> 450 | N15: =K15*#REF! -> #REF! | O15: =M15*#REF! -> #REF! | P15: 0 | R15: =SUM(N15:Q15) -> #REF!
B16: 14 | C16: Redhat OCP Infra Router | D16: Container Platform | E16: Enterprise | F16: DC2 | G16: 5 | H16: 8 | I16: 32 | J16: 150 | K16: =H16*G16 -> 40 | L16: =I16*G16 -> 160 | M16: =J16*G16 -> 750 | N16: =K16*#REF! -> #REF! | O16: =M16*#REF! -> #REF! | P16: 0 | R16: =SUM(N16:Q16) -> #REF!
B17: 15 | C17: Redhat OCP Worker (Baremetal) | D17: Container Platform | E17: Enterprise | F17: DC2 | G17: 1 | H17: 64 | I17: 1024 | J17: 1024 | K17: =H17*G17 -> 64 | L17: =I17*G17 -> 1024 | M17: =J17*G17 -> 1024 | N17: 0 | O17: 0 | P17: 0 | Q17: =G17*#REF! -> #REF! | R17: =SUM(N17:Q17) -> #REF!
B18: 16 | C18: Bastion & HA Proxy | D18: Bastion | E18: Enterprise | F18: DC2 | G18: 1 | H18: 4 | I18: 8 | J18: 100 | K18: =H18*G18 -> 4 | L18: =I18*G18 -> 8 | M18: =J18*G18 -> 100 | N18: =K18*#REF! -> #REF! | O18: =M18*#REF! -> #REF! | P18: 0 | R18: =SUM(N18:Q18) -> #REF!
B19: 17 | C19: Oracle Database RAC (Baremetal) | D19: Database | E19: Enterprise | F19: DC2 | G19: 2 | H19: 64 | I19: 1024 | J19: 423000 | K19: =H19*G19 -> 128 | L19: =I19*G19 -> 2048 | M19: =J19 -> 423000 | N19: 0 | O19: =M19*#REF! -> #REF! | P19: =M19*50%*80%*#REF! -> #REF! | Q19: =G19*#REF! -> #REF! | R19: =SUM(N19:Q19) -> #REF!
B20: 18 | C20: Nginx Community | D20: Application Gateway | E20: Community | F20: DC2 | G20: 2 | H20: 8 | I20: 16 | J20: 200 | K20: =H20*G20 -> 16 | L20: =I20*G20 -> 32 | M20: =J20*G20 -> 400 | N20: =K20*#REF! -> #REF! | O20: =M20*#REF! -> #REF! | R20: =SUM(N20:Q20) -> #REF!
B21: 19 | C21: Redis Enterprise | D21: Cache Database | E21: Enterprise | F21: DC2 | G21: 3 | H21: 8 | I21: 16 | J21: 200 | K21: =H21*G21 -> 24 | L21: =I21*G21 -> 48 | M21: =J21*G21 -> 600 | N21: =K21*#REF! -> #REF! | O21: =M21*#REF! -> #REF! | R21: =SUM(N21:Q21) -> #REF!
B22: 20 | C22: Confluent Kafka Community App Log (Non Financial) | D22: Kafka Broker & Zookeeper | E22: Community | F22: DC2 | G22: 3 | H22: 8 | I22: 16 | J22: 1000 | K22: =H22*G22 -> 24 | L22: =I22*G22 -> 48 | M22: =J22*G22 -> 3000 | N22: =K22*#REF! -> #REF! | O22: =M22*#REF! -> #REF! | R22: =SUM(N22:Q22) -> #REF!
B23: 21 | C23: Batch Control M | D23: Batch Server | E23: Enterprise | F23: DC2 | G23: 1 | H23: 8 | I23: 16 | J23: 500 | K23: =H23*G23 -> 8 | L23: =I23*G23 -> 16 | M23: =J23*G23 -> 500 | N23: =K23*#REF! -> #REF! | O23: =M23*#REF! -> #REF! | R23: =SUM(N23:Q23) -> #REF!
B24: 22 | C24: MinIO | D24: Object Storage | E24: Community | F24: DC2 | G24: 1 | H24: 16 | I24: 32 | J24: 500 | K24: =H24*G24 -> 16 | L24: =I24*G24 -> 32 | M24: =J24*G24 -> 500 | N24: =K24*#REF! -> #REF! | O24: =M24*#REF! -> #REF! | R24: =SUM(N24:Q24) -> #REF!
B25: 23 | C25: Elasticsearch Master & Data | D25: ELK Stack | E25: Community | F25: DC2 | G25: 3 | H25: 8 | I25: 32 | J25: 300 | K25: =H25*G25 -> 24 | L25: =I25*G25 -> 96 | M25: =J25*G25 -> 900 | N25: =K25*#REF! -> #REF! | O25: =M25*#REF! -> #REF! | R25: =SUM(N25:Q25) -> #REF!
B26: 24 | C26: Kibana Logstash | D26: ELK Stack | E26: Community | F26: DC2 | G26: 1 | H26: 8 | I26: 16 | J26: 300 | K26: =H26*G26 -> 8 | L26: =I26*G26 -> 16 | M26: =J26*G26 -> 300 | N26: =K26*#REF! -> #REF! | O26: =M26*#REF! -> #REF! | R26: =SUM(N26:Q26) -> #REF!
B28: 25 | C28: Redhat OCP Master | D28: Container Platform | E28: Enterprise | F28: PT | G28: 3 | H28: 8 | I28: 32 | J28: 150 | K28: =H28*G28 -> 24 | L28: =I28*G28 -> 96 | M28: =J28*G28 -> 450 | N28: =K28*#REF! -> #REF! | O28: =M28*#REF! -> #REF! | R28: =SUM(N28:Q28) -> #REF!
B29: 26 | C29: Redhat OCP Infra Router | D29: Container Platform | E29: Enterprise | F29: PT | G29: 5 | H29: 8 | I29: 32 | J29: 150 | K29: =H29*G29 -> 40 | L29: =I29*G29 -> 160 | M29: =J29*G29 -> 750 | N29: =K29*#REF! -> #REF! | O29: =M29*#REF! -> #REF! | R29: =SUM(N29:Q29) -> #REF!
B30: 27 | C30: Redhat OCP Worker (Baremetal) | D30: Container Platform | E30: Enterprise | F30: PT | G30: 1 | H30: 64 | I30: 1024 | J30: 1024 | K30: =H30*G30 -> 64 | L30: =I30*G30 -> 1024 | M30: =J30*G30 -> 1024 | N30: 0 | O30: 0 | Q30: =G30*#REF! -> #REF! | R30: =SUM(N30:Q30) -> #REF!
B31: 28 | C31: Bastion & HA Proxy | D31: Bastion | E31: Enterprise | F31: PT | G31: 1 | H31: 4 | I31: 8 | J31: 100 | K31: =H31*G31 -> 4 | L31: =I31*G31 -> 8 | M31: =J31*G31 -> 100 | N31: =K31*#REF! -> #REF! | O31: =M31*#REF! -> #REF! | R31: =SUM(N31:Q31) -> #REF!
B32: 29 | C32: Oracle Database RAC (Baremetal) | D32: Database | E32: Enterprise | F32: PT | G32: 2 | H32: 64 | I32: 1024 | J32: 13000 | K32: =H32*G32 -> 128 | L32: =I32*G32 -> 2048 | M32: 13000 | N32: 0 | O32: =M32*#REF! -> #REF! | Q32: =G32*#REF! -> #REF! | R32: =SUM(N32:Q32) -> #REF!
B33: 30 | C33: Nginx Community | D33: Application Gateway | E33: Community | F33: PT | G33: 2 | H33: 8 | I33: 16 | J33: 200 | K33: =H33*G33 -> 16 | L33: =I33*G33 -> 32 | M33: =J33*G33 -> 400 | N33: =K33*#REF! -> #REF! | O33: =M33*#REF! -> #REF! | R33: =SUM(N33:Q33) -> #REF!
B34: 31 | C34: Redis Enterprise | D34: Cache Database | E34: Enterprise | F34: PT | G34: 3 | H34: 8 | I34: 16 | J34: 200 | K34: =H34*G34 -> 24 | L34: =I34*G34 -> 48 | M34: =J34*G34 -> 600 | N34: =K34*#REF! -> #REF! | O34: =M34*#REF! -> #REF! | R34: =SUM(N34:Q34) -> #REF!
B35: 32 | C35: Confluent Kafka Community App Log (Non Financial) | D35: Kafka Broker & Zookeeper | E35: Community | F35: PT | G35: 3 | H35: 8 | I35: 16 | J35: 1000 | K35: =H35*G35 -> 24 | L35: =I35*G35 -> 48 | M35: =J35*G35 -> 3000 | N35: =K35*#REF! -> #REF! | O35: =M35*#REF! -> #REF! | R35: =SUM(N35:Q35) -> #REF!
B36: 33 | C36: Batch Control M | D36: Batch Server | E36: Enterprise | F36: PT | G36: 1 | H36: 8 | I36: 16 | J36: 500 | K36: =H36*G36 -> 8 | L36: =I36*G36 -> 16 | M36: =J36*G36 -> 500 | N36: =K36*#REF! -> #REF! | O36: =M36*#REF! -> #REF! | R36: =SUM(N36:Q36) -> #REF!
B37: 34 | C37: MinIO | D37: Object Storage | E37: Enterprise | F37: PT | G37: 1 | H37: 16 | I37: 32 | J37: 500 | K37: =H37*G37 -> 16 | L37: =I37*G37 -> 32 | M37: =J37*G37 -> 500 | N37: =K37*#REF! -> #REF! | O37: =M37*#REF! -> #REF! | R37: =SUM(N37:Q37) -> #REF!
B38: 35 | C38: Elasticsearch Master & Data | D38: ELK Stack | E38: Community | F38: PT | G38: 3 | H38: 8 | I38: 32 | J38: 300 | K38: =H38*G38 -> 24 | L38: =I38*G38 -> 96 | M38: =J38*G38 -> 900 | N38: =K38*#REF! -> #REF! | O38: =M38*#REF! -> #REF! | R38: =SUM(N38:Q38) -> #REF!
B39: 36 | C39: Kibana Logstash | D39: ELK Stack | E39: Community | F39: PT | G39: 1 | H39: 8 | I39: 16 | J39: 300 | K39: =H39*G39 -> 8 | L39: =I39*G39 -> 16 | M39: =J39*G39 -> 300 | N39: =K39*#REF! -> #REF! | O39: =M39*#REF! -> #REF! | R39: =SUM(N39:Q39) -> #REF!
B40: 37 | C40: Wiremock | D40: Wiremock | E40: Community | F40: PT | G40: 2 | H40: 8 | I40: 24 | J40: 128 | K40: =H40*G40 -> 16 | L40: =I40*G40 -> 48 | M40: =J40*G40 -> 256 | N40: =K40*#REF! -> #REF! | O40: =M40*#REF! -> #REF! | R40: =SUM(N40:Q40) -> #REF!
B42: 38 | C42: Oracle Database (VM) | D42: Database | E42: Enterprise | F42: DEV & UAT | G42: 1 | H42: 16 | I42: 32 | J42: =2500 -> 2500 | K42: =H42*G42 -> 16 | L42: 64 | M42: =J42*G42 -> 2500 | N42: =K42*#REF! -> #REF! | O42: =M42*#REF! -> #REF! | R42: {=[1]OS!$D$30:$D$321} -> #VALUE!
...

Sheet FS Opsi Oracle 20260620
B1: Summary Hardware
B2: No | C2: Group | D2: Description | E2: Edition | F2: Environment | G2: # of VM | H2: CPU | I2: Memory | J2: Storage | K2: Total CPU | L2: Total Memory | M2: Total Storage | N2: Pricing CPU | O2: Pricing Storage | P2: Pricing Rubrik / NBU | Q2: Pricing Baremetal | R2: Total
B3: 1 | C3: Redhat OCP Master | D3: Container Platform | E3: Enterprise | F3: DC1 | G3: 3 | H3: 8 | I3: 32 | J3: 150 | K3: =H3*G3 -> 24 | L3: =I3*G3 -> 96 | M3: =J3*G3 -> 450 | N3: =K3*#REF! -> #REF! | O3: =M3*#REF! -> #REF! | P3: 0 | R3: =SUM(N3:Q3) -> #REF!
B4: 2 | C4: Redhat OCP Infra Router | D4: Container Platform | E4: Enterprise | F4: DC1 | G4: 5 | H4: 8 | I4: 32 | J4: 150 | K4: =H4*G4 -> 40 | L4: =I4*G4 -> 160 | M4: =J4*G4 -> 750 | N4: =K4*#REF! -> #REF! | O4: =M4*#REF! -> #REF! | P4: 0 | R4: =SUM(N4:Q4) -> #REF!
B5: 3 | C5: Redhat OCP Worker (Baremetal) | D5: Container Platform | E5: Enterprise | F5: DC1 | G5: 1 | H5: 64 | I5: 1024 | J5: 1024 | K5: =H5*G5 -> 64 | L5: =I5*G5 -> 1024 | M5: =J5*G5 -> 1024 | N5: 0 | O5: 0 | P5: 0 | Q5: =G5*#REF! -> #REF! | R5: =SUM(N5:Q5) -> #REF!
B6: 4 | C6: Bastion & HA Proxy | D6: Bastion | E6: Enterprise | F6: DC1 | G6: 1 | H6: 4 | I6: 8 | J6: 100 | K6: =H6*G6 -> 4 | L6: =I6*G6 -> 8 | M6: =J6*G6 -> 100 | N6: =K6*#REF! -> #REF! | O6: =M6*#REF! -> #REF! | P6: 0 | R6: =SUM(N6:Q6) -> #REF!
B7: 5 | C7: Oracle Database RAC (Baremetal) | D7: Database | E7: Enterprise | F7: DC1 | G7: 2 | H7: 64 | I7: 1024 | J7: 60000 | K7: =H7*G7 -> 128 | L7: =I7*G7 -> 2048 | M7: =J7 -> 60000 | N7: 0 | O7: =M7*#REF! -> #REF! | P7: =M7*50%*80%*#REF! -> #REF! | Q7: =G7*#REF! -> #REF! | R7: =SUM(N7:Q7) -> #REF!
B8: 6 | C8: Nginx Community | D8: Application Gateway | E8: Community | F8: DC1 | G8: 2 | H8: 8 | I8: 16 | J8: 200 | K8: =H8*G8 -> 16 | L8: =I8*G8 -> 32 | M8: =G8*J8 -> 400 | N8: =K8*#REF! -> #REF! | O8: =M8*#REF! -> #REF! | R8: =SUM(N8:Q8) -> #REF!
B9: 7 | C9: Redis Enterprise | D9: Cache Database | E9: Enterprise | F9: DC1 | G9: 3 | H9: 8 | I9: 16 | J9: 200 | K9: =H9*G9 -> 24 | L9: =I9*G9 -> 48 | M9: =G9*J9 -> 600 | N9: =K9*#REF! -> #REF! | O9: =M9*#REF! -> #REF! | R9: =SUM(N9:Q9) -> #REF!
B10: 8 | C10: Confluent Kafka Community App Log (Non Financial) | D10: Kafka Broker & Zookeeper | E10: Community | F10: DC1 | G10: 3 | H10: 8 | I10: 16 | J10: 1000 | K10: =H10*G10 -> 24 | L10: =I10*G10 -> 48 | M10: =G10*J10 -> 3000 | N10: =K10*#REF! -> #REF! | O10: =M10*#REF! -> #REF! | R10: =SUM(N10:Q10) -> #REF!
B11: 9 | C11: Batch Control M | D11: Batch Server | E11: Enterprise | F11: DC1 | G11: 1 | H11: 8 | I11: 16 | J11: 500 | K11: =H11*G11 -> 8 | L11: =I11*G11 -> 16 | M11: =G11*J11 -> 500 | N11: =K11*#REF! -> #REF! | O11: =M11*#REF! -> #REF! | R11: =SUM(N11:Q11) -> #REF!
B12: 10 | C12: MinIO | D12: Object Storage | E12: Community | F12: DC1 | G12: 1 | H12: 16 | I12: 32 | J12: 500 | K12: =H12*G12 -> 16 | L12: =I12*G12 -> 32 | M12: =G12*J12 -> 500 | N12: =K12*#REF! -> #REF! | O12: =M12*#REF! -> #REF! | R12: =SUM(N12:Q12) -> #REF!
B13: 11 | C13: Elasticsearch Master & Data | D13: ELK Stack | E13: Community | F13: DC1 | G13: 3 | H13: 8 | I13: 32 | J13: 300 | K13: =H13*G13 -> 24 | L13: =I13*G13 -> 96 | M13: =G13*J13 -> 900 | N13: =K13*#REF! -> #REF! | O13: =M13*#REF! -> #REF! | R13: =SUM(N13:Q13) -> #REF!
B14: 12 | C14: Kibana Logstash | D14: ELK Stack | E14: Community | F14: DC1 | G14: 1 | H14: 8 | I14: 16 | J14: 300 | K14: =H14*G14 -> 8 | L14: =I14*G14 -> 16 | M14: =G14*J14 -> 300 | N14: =K14*#REF! -> #REF! | O14: =M14*#REF! -> #REF! | R14: =SUM(N14:Q14) -> #REF!
B15: 13 | C15: Redhat OCP Master | D15: Container Platform | E15: Enterprise | F15: DC2 | G15: 3 | H15: 8 | I15: 32 | J15: 150 | K15: =H15*G15 -> 24 | L15: =I15*G15 -> 96 | M15: =J15*G15 -> 450 | N15: =K15*#REF! -> #REF! | O15: =M15*#REF! -> #REF! | P15: 0 | R15: =SUM(N15:Q15) -> #REF!
B16: 14 | C16: Redhat OCP Infra Router | D16: Container Platform | E16: Enterprise | F16: DC2 | G16: 5 | H16: 8 | I16: 32 | J16: 150 | K16: =H16*G16 -> 40 | L16: =I16*G16 -> 160 | M16: =J16*G16 -> 750 | N16: =K16*#REF! -> #REF! | O16: =M16*#REF! -> #REF! | P16: 0 | R16: =SUM(N16:Q16) -> #REF!
B17: 15 | C17: Redhat OCP Worker (Baremetal) | D17: Container Platform | E17: Enterprise | F17: DC2 | G17: 1 | H17: 64 | I17: 1024 | J17: 1024 | K17: =H17*G17 -> 64 | L17: =I17*G17 -> 1024 | M17: =J17*G17 -> 1024 | N17: 0 | O17: 0 | P17: 0 | Q17: =G17*#REF! -> #REF! | R17: =SUM(N17:Q17) -> #REF!
B18: 16 | C18: Bastion & HA Proxy | D18: Bastion | E18: Enterprise | F18: DC2 | G18: 1 | H18: 4 | I18: 8 | J18: 100 | K18: =H18*G18 -> 4 | L18: =I18*G18 -> 8 | M18: =J18*G18 -> 100 | N18: =K18*#REF! -> #REF! | O18: =M18*#REF! -> #REF! | P18: 0 | R18: =SUM(N18:Q18) -> #REF!
B19: 17 | C19: Oracle Database RAC (Baremetal) | D19: Database | E19: Enterprise | F19: DC2 | G19: 2 | H19: 64 | I19: 1024 | J19: 60000 | K19: =H19*G19 -> 128 | L19: =I19*G19 -> 2048 | M19: =J19 -> 60000 | N19: 0 | O19: =M19*#REF! -> #REF! | P19: =M19*50%*80%*#REF! -> #REF! | Q19: =G19*#REF! -> #REF! | R19: =SUM(N19:Q19) -> #REF!
B20: 18 | C20: Nginx Community | D20: Application Gateway | E20: Community | F20: DC2 | G20: 2 | H20: 8 | I20: 16 | J20: 200 | K20: =H20*G20 -> 16 | L20: =I20*G20 -> 32 | M20: =J20*G20 -> 400 | N20: =K20*#REF! -> #REF! | O20: =M20*#REF! -> #REF! | R20: =SUM(N20:Q20) -> #REF!
B21: 19 | C21: Redis Enterprise | D21: Cache Database | E21: Enterprise | F21: DC2 | G21: 3 | H21: 8 | I21: 16 | J21: 200 | K21: =H21*G21 -> 24 | L21: =I21*G21 -> 48 | M21: =J21*G21 -> 600 | N21: =K21*#REF! -> #REF! | O21: =M21*#REF! -> #REF! | R21: =SUM(N21:Q21) -> #REF!
B22: 20 | C22: Confluent Kafka Community App Log (Non Financial) | D22: Kafka Broker & Zookeeper | E22: Community | F22: DC2 | G22: 3 | H22: 8 | I22: 16 | J22: 1000 | K22: =H22*G22 -> 24 | L22: =I22*G22 -> 48 | M22: =J22*G22 -> 3000 | N22: =K22*#REF! -> #REF! | O22: =M22*#REF! -> #REF! | R22: =SUM(N22:Q22) -> #REF!
B23: 21 | C23: Batch Control M | D23: Batch Server | E23: Enterprise | F23: DC2 | G23: 1 | H23: 8 | I23: 16 | J23: 500 | K23: =H23*G23 -> 8 | L23: =I23*G23 -> 16 | M23: =J23*G23 -> 500 | N23: =K23*#REF! -> #REF! | O23: =M23*#REF! -> #REF! | R23: =SUM(N23:Q23) -> #REF!
B24: 22 | C24: MinIO | D24: Object Storage | E24: Community | F24: DC2 | G24: 1 | H24: 16 | I24: 32 | J24: 500 | K24: =H24*G24 -> 16 | L24: =I24*G24 -> 32 | M24: =J24*G24 -> 500 | N24: =K24*#REF! -> #REF! | O24: =M24*#REF! -> #REF! | R24: =SUM(N24:Q24) -> #REF! | T24: Strg DB Prod | U24: =M7*2 -> 120000 | V24: =U24/U25 -> 9.2307692
B25: 23 | C25: Elasticsearch Master & Data | D25: ELK Stack | E25: Community | F25: DC2 | G25: 3 | H25: 8 | I25: 32 | J25: 300 | K25: =H25*G25 -> 24 | L25: =I25*G25 -> 96 | M25: =J25*G25 -> 900 | N25: =K25*#REF! -> #REF! | O25: =M25*#REF! -> #REF! | R25: =SUM(N25:Q25) -> #REF! | T25: Strg DB PT | U25: =M32 -> 13000 | V25: 1
B26: 24 | C26: Kibana Logstash | D26: ELK Stack | E26: Community | F26: DC2 | G26: 1 | H26: 8 | I26: 16 | J26: 300 | K26: =H26*G26 -> 8 | L26: =I26*G26 -> 16 | M26: =J26*G26 -> 300 | N26: =K26*#REF! -> #REF! | O26: =M26*#REF! -> #REF! | R26: =SUM(N26:Q26) -> #REF!
B28: 25 | C28: Redhat OCP Master | D28: Container Platform | E28: Enterprise | F28: PT | G28: 3 | H28: 8 | I28: 32 | J28: 150 | K28: =H28*G28 -> 24 | L28: =I28*G28 -> 96 | M28: =J28*G28 -> 450 | N28: =K28*#REF! -> #REF! | O28: =M28*#REF! -> #REF! | R28: =SUM(N28:Q28) -> #REF!
B29: 26 | C29: Redhat OCP Infra Router | D29: Container Platform | E29: Enterprise | F29: PT | G29: 5 | H29: 8 | I29: 32 | J29: 150 | K29: =H29*G29 -> 40 | L29: =I29*G29 -> 160 | M29: =J29*G29 -> 750 | N29: =K29*#REF! -> #REF! | O29: =M29*#REF! -> #REF! | R29: =SUM(N29:Q29) -> #REF! | T29: Strg Prod | U29: =SUM(M3:M26) -> 137048 | V29: =U29/U30 -> 6.367218
B30: 27 | C30: Redhat OCP Worker (Baremetal) | D30: Container Platform | E30: Enterprise | F30: PT | G30: 1 | H30: 64 | I30: 1024 | J30: 1024 | K30: =H30*G30 -> 64 | L30: =I30*G30 -> 1024 | M30: =J30*G30 -> 1024 | N30: 0 | O30: 0 | Q30: =G30*#REF! -> #REF! | R30: =SUM(N30:Q30) -> #REF! | T30: Strg PT | U30: =SUM(M28:M39) -> 21524 | V30: =1 -> 1
B31: 28 | C31: Bastion & HA Proxy | D31: Bastion | E31: Enterprise | F31: PT | G31: 1 | H31: 4 | I31: 8 | J31: 100 | K31: =H31*G31 -> 4 | L31: =I31*G31 -> 8 | M31: =J31*G31 -> 100 | N31: =K31*#REF! -> #REF! | O31: =M31*#REF! -> #REF! | R31: =SUM(N31:Q31) -> #REF!
B32: 29 | C32: Oracle Database RAC (Baremetal) | D32: Database | E32: Enterprise | F32: PT | G32: 2 | H32: 64 | I32: 1024 | J32: 13000 | K32: =H32*G32 -> 128 | L32: =I32*G32 -> 2048 | M32: 13000 | N32: 0 | O32: =M32*#REF! -> #REF! | Q32: =G32*#REF! -> #REF! | R32: =SUM(N32:Q32) -> #REF! | T32: Memoru Prod | U32: =SUM(L3:L26) -> 7248 | V32: =U32/U33 -> 1.9738562
B33: 30 | C33: Nginx Community | D33: Application Gateway | E33: Community | F33: PT | G33: 2 | H33: 8 | I33: 16 | J33: 200 | K33: =H33*G33 -> 16 | L33: =I33*G33 -> 32 | M33: =J33*G33 -> 400 | N33: =K33*#REF! -> #REF! | O33: =M33*#REF! -> #REF! | R33: =SUM(N33:Q33) -> #REF! | T33: Memory PT | U33: =SUM(L28:L40) -> 3672 | V33: 1
B34: 31 | C34: Redis Enterprise | D34: Cache Database | E34: Enterprise | F34: PT | G34: 3 | H34: 8 | I34: 16 | J34: 200 | K34: =H34*G34 -> 24 | L34: =I34*G34 -> 48 | M34: =J34*G34 -> 600 | N34: =K34*#REF! -> #REF! | O34: =M34*#REF! -> #REF! | R34: =SUM(N34:Q34) -> #REF!
B35: 32 | C35: Confluent Kafka Community App Log (Non Financial) | D35: Kafka Broker & Zookeeper | E35: Community | F35: PT | G35: 3 | H35: 8 | I35: 16 | J35: 1000 | K35: =H35*G35 -> 24 | L35: =I35*G35 -> 48 | M35: =J35*G35 -> 3000 | N35: =K35*#REF! -> #REF! | O35: =M35*#REF! -> #REF! | R35: =SUM(N35:Q35) -> #REF! | T35: CPU Prod
B36: 33 | C36: Batch Control M | D36: Batch Server | E36: Enterprise | F36: PT | G36: 1 | H36: 8 | I36: 16 | J36: 500 | K36: =H36*G36 -> 8 | L36: =I36*G36 -> 16 | M36: =J36*G36 -> 500 | N36: =K36*#REF! -> #REF! | O36: =M36*#REF! -> #REF! | R36: =SUM(N36:Q36) -> #REF! | T36: CPU Dev
B37: 34 | C37: MinIO | D37: Object Storage | E37: Enterprise | F37: PT | G37: 1 | H37: 16 | I37: 32 | J37: 500 | K37: =H37*G37 -> 16 | L37: =I37*G37 -> 32 | M37: =J37*G37 -> 500 | N37: =K37*#REF! -> #REF! | O37: =M37*#REF! -> #REF! | R37: =SUM(N37:Q37) -> #REF!
B38: 35 | C38: Elasticsearch Master & Data | D38: ELK Stack | E38: Community | F38: PT | G38: 3 | H38: 8 | I38: 32 | J38: 300 | K38: =H38*G38 -> 24 | L38: =I38*G38 -> 96 | M38: =J38*G38 -> 900 | N38: =K38*#REF! -> #REF! | O38: =M38*#REF! -> #REF! | R38: =SUM(N38:Q38) -> #REF!
B39: 36 | C39: Kibana Logstash | D39: ELK Stack | E39: Community | F39: PT | G39: 1 | H39: 8 | I39: 16 | J39: 300 | K39: =H39*G39 -> 8 | L39: =I39*G39 -> 16 | M39: =J39*G39 -> 300 | N39: =K39*#REF! -> #REF! | O39: =M39*#REF! -> #REF! | R39: =SUM(N39:Q39) -> #REF!
B40: 37 | C40: Wiremock | D40: Wiremock | E40: Community | F40: PT | G40: 2 | H40: 8 | I40: 24 | J40: 128 | K40: =H40*G40 -> 16 | L40: =I40*G40 -> 48 | M40: =J40*G40 -> 256 | N40: =K40*#REF! -> #REF! | O40: =M40*#REF! -> #REF! | R40: =SUM(N40:Q40) -> #REF!
B42: 38 | C42: Oracle Database (VM) | D42: Database | E42: Enterprise | F42: DEV & UAT | G42: 1 | H42: 16 | I42: 32 | J42: =2500 -> 2500 | K42: =H42*G42 -> 16 | L42: 64 | M42: =J42*G42 -> 2500 | N42: =K42*#REF! -> #REF! | O42: =M42*#REF! -> #REF! | R42: =SUM(N42:Q42) -> #REF!
...

Sheet FS Opsi Oracle RAC T3
B1: Summary Hardware
B2: No | C2: Group | D2: Description | E2: Edition | F2: Environment | G2: # of VM | H2: CPU | I2: Memory | J2: Storage | K2: Total CPU | L2: Total Memory | M2: Total Storage | N2: Pricing CPU | O2: Pricing Storage | P2: Pricing Rubrik / NBU | Q2: Pricing Baremetal | R2: Total
B3: 1 | C3: Redhat OCP Master | D3: Container Platform | E3: Enterprise | F3: DC1 | G3: 3 | H3: 8 | I3: 32 | J3: 150 | K3: =H3*G3 -> 24 | L3: =I3*G3 -> 96 | M3: =J3*G3 -> 450 | N3: =K3*#REF! -> #REF! | O3: =M3*#REF! -> #REF! | P3: 0 | R3: =SUM(N3:Q3) -> #REF!
B4: 2 | C4: Redhat OCP Infra Router | D4: Container Platform | E4: Enterprise | F4: DC1 | G4: 5 | H4: 8 | I4: 32 | J4: 150 | K4: =H4*G4 -> 40 | L4: =I4*G4 -> 160 | M4: =J4*G4 -> 750 | N4: =K4*#REF! -> #REF! | O4: =M4*#REF! -> #REF! | P4: 0 | R4: =SUM(N4:Q4) -> #REF!
B5: 3 | C5: Redhat OCP Worker (Baremetal) | D5: Container Platform | E5: Enterprise | F5: DC1 | G5: 1 | H5: 64 | I5: 1024 | J5: 1024 | K5: =H5*G5 -> 64 | L5: =I5*G5 -> 1024 | M5: =J5*G5 -> 1024 | N5: 0 | O5: 0 | P5: 0 | Q5: =G5*#REF! -> #REF! | R5: =SUM(N5:Q5) -> #REF!
B6: 4 | C6: Bastion & HA Proxy | D6: Bastion | E6: Enterprise | F6: DC1 | G6: 1 | H6: 4 | I6: 8 | J6: 100 | K6: =H6*G6 -> 4 | L6: =I6*G6 -> 8 | M6: =J6*G6 -> 100 | N6: =K6*#REF! -> #REF! | O6: =M6*#REF! -> #REF! | P6: 0 | R6: =SUM(N6:Q6) -> #REF!
B7: 5 | C7: Oracle Database RAC (Baremetal) | D7: Database | E7: Enterprise | F7: DC1 | G7: 2 | H7: 64 | I7: 1024 | J7: 60000 | K7: =H7*G7 -> 128 | L7: =I7*G7 -> 2048 | M7: =J7 -> 60000 | N7: 0 | O7: =M7*#REF! -> #REF! | P7: =M7*50%*80%*#REF! -> #REF! | Q7: =G7*#REF! -> #REF! | R7: =SUM(N7:Q7) -> #REF!
B8: 6 | C8: Nginx Community | D8: Application Gateway | E8: Community | F8: DC1 | G8: 2 | H8: 8 | I8: 16 | J8: 200 | K8: =H8*G8 -> 16 | L8: =I8*G8 -> 32 | M8: =G8*J8 -> 400 | N8: =K8*#REF! -> #REF! | O8: =M8*#REF! -> #REF! | R8: =SUM(N8:Q8) -> #REF!
B9: 7 | C9: Redis Enterprise | D9: Cache Database | E9: Enterprise | F9: DC1 | G9: 3 | H9: 8 | I9: 16 | J9: 200 | K9: =H9*G9 -> 24 | L9: =I9*G9 -> 48 | M9: =G9*J9 -> 600 | N9: =K9*#REF! -> #REF! | O9: =M9*#REF! -> #REF! | R9: =SUM(N9:Q9) -> #REF!
B10: 8 | C10: Confluent Kafka Community App Log (Non Financial) | D10: Kafka Broker & Zookeeper | E10: Community | F10: DC1 | G10: 3 | H10: 8 | I10: 16 | J10: 1000 | K10: =H10*G10 -> 24 | L10: =I10*G10 -> 48 | M10: =G10*J10 -> 3000 | N10: =K10*#REF! -> #REF! | O10: =M10*#REF! -> #REF! | R10: =SUM(N10:Q10) -> #REF!
B11: 9 | C11: Batch Control M | D11: Batch Server | E11: Enterprise | F11: DC1 | G11: 1 | H11: 8 | I11: 16 | J11: 500 | K11: =H11*G11 -> 8 | L11: =I11*G11 -> 16 | M11: =G11*J11 -> 500 | N11: =K11*#REF! -> #REF! | O11: =M11*#REF! -> #REF! | R11: =SUM(N11:Q11) -> #REF!
B12: 10 | C12: MinIO | D12: Object Storage | E12: Community | F12: DC1 | G12: 1 | H12: 16 | I12: 32 | J12: 500 | K12: =H12*G12 -> 16 | L12: =I12*G12 -> 32 | M12: =G12*J12 -> 500 | N12: =K12*#REF! -> #REF! | O12: =M12*#REF! -> #REF! | R12: =SUM(N12:Q12) -> #REF!
B13: 11 | C13: Elasticsearch Master & Data | D13: ELK Stack | E13: Community | F13: DC1 | G13: 3 | H13: 8 | I13: 32 | J13: 300 | K13: =H13*G13 -> 24 | L13: =I13*G13 -> 96 | M13: =G13*J13 -> 900 | N13: =K13*#REF! -> #REF! | O13: =M13*#REF! -> #REF! | R13: =SUM(N13:Q13) -> #REF!
B14: 12 | C14: Kibana Logstash | D14: ELK Stack | E14: Community | F14: DC1 | G14: 1 | H14: 8 | I14: 16 | J14: 300 | K14: =H14*G14 -> 8 | L14: =I14*G14 -> 16 | M14: =G14*J14 -> 300 | N14: =K14*#REF! -> #REF! | O14: =M14*#REF! -> #REF! | R14: =SUM(N14:Q14) -> #REF!
B15: 13 | C15: Redhat OCP Master | D15: Container Platform | E15: Enterprise | F15: DC2 | G15: 3 | H15: 8 | I15: 32 | J15: 150 | K15: =H15*G15 -> 24 | L15: =I15*G15 -> 96 | M15: =J15*G15 -> 450 | N15: =K15*#REF! -> #REF! | O15: =M15*#REF! -> #REF! | P15: 0 | R15: =SUM(N15:Q15) -> #REF!
B16: 14 | C16: Redhat OCP Infra Router | D16: Container Platform | E16: Enterprise | F16: DC2 | G16: 5 | H16: 8 | I16: 32 | J16: 150 | K16: =H16*G16 -> 40 | L16: =I16*G16 -> 160 | M16: =J16*G16 -> 750 | N16: =K16*#REF! -> #REF! | O16: =M16*#REF! -> #REF! | P16: 0 | R16: =SUM(N16:Q16) -> #REF!
B17: 15 | C17: Redhat OCP Worker (Baremetal) | D17: Container Platform | E17: Enterprise | F17: DC2 | G17: 1 | H17: 64 | I17: 1024 | J17: 1024 | K17: =H17*G17 -> 64 | L17: =I17*G17 -> 1024 | M17: =J17*G17 -> 1024 | N17: 0 | O17: 0 | P17: 0 | Q17: =G17*#REF! -> #REF! | R17: =SUM(N17:Q17) -> #REF!
B18: 16 | C18: Bastion & HA Proxy | D18: Bastion | E18: Enterprise | F18: DC2 | G18: 1 | H18: 4 | I18: 8 | J18: 100 | K18: =H18*G18 -> 4 | L18: =I18*G18 -> 8 | M18: =J18*G18 -> 100 | N18: =K18*#REF! -> #REF! | O18: =M18*#REF! -> #REF! | P18: 0 | R18: =SUM(N18:Q18) -> #REF!
B19: 17 | C19: Oracle Database RAC (Baremetal) | D19: Database | E19: Enterprise | F19: DC2 | G19: 2 | H19: 64 | I19: 1024 | J19: 60000 | K19: =H19*G19 -> 128 | L19: =I19*G19 -> 2048 | M19: =J19 -> 60000 | N19: 0 | O19: =M19*#REF! -> #REF! | P19: =M19*50%*80%*#REF! -> #REF! | Q19: =G19*#REF! -> #REF! | R19: =SUM(N19:Q19) -> #REF!
B20: 18 | C20: Nginx Community | D20: Application Gateway | E20: Community | F20: DC2 | G20: 2 | H20: 8 | I20: 16 | J20: 200 | K20: =H20*G20 -> 16 | L20: =I20*G20 -> 32 | M20: =J20*G20 -> 400 | N20: =K20*#REF! -> #REF! | O20: =M20*#REF! -> #REF! | R20: =SUM(N20:Q20) -> #REF!
B21: 19 | C21: Redis Enterprise | D21: Cache Database | E21: Enterprise | F21: DC2 | G21: 3 | H21: 8 | I21: 16 | J21: 200 | K21: =H21*G21 -> 24 | L21: =I21*G21 -> 48 | M21: =J21*G21 -> 600 | N21: =K21*#REF! -> #REF! | O21: =M21*#REF! -> #REF! | R21: =SUM(N21:Q21) -> #REF!
B22: 20 | C22: Confluent Kafka Community App Log (Non Financial) | D22: Kafka Broker & Zookeeper | E22: Community | F22: DC2 | G22: 3 | H22: 8 | I22: 16 | J22: 1000 | K22: =H22*G22 -> 24 | L22: =I22*G22 -> 48 | M22: =J22*G22 -> 3000 | N22: =K22*#REF! -> #REF! | O22: =M22*#REF! -> #REF! | R22: =SUM(N22:Q22) -> #REF!
B23: 21 | C23: Batch Control M | D23: Batch Server | E23: Enterprise | F23: DC2 | G23: 1 | H23: 8 | I23: 16 | J23: 500 | K23: =H23*G23 -> 8 | L23: =I23*G23 -> 16 | M23: =J23*G23 -> 500 | N23: =K23*#REF! -> #REF! | O23: =M23*#REF! -> #REF! | R23: =SUM(N23:Q23) -> #REF!
B24: 22 | C24: MinIO | D24: Object Storage | E24: Community | F24: DC2 | G24: 1 | H24: 16 | I24: 32 | J24: 500 | K24: =H24*G24 -> 16 | L24: =I24*G24 -> 32 | M24: =J24*G24 -> 500 | N24: =K24*#REF! -> #REF! | O24: =M24*#REF! -> #REF! | R24: =SUM(N24:Q24) -> #REF! | T24: Strg DB Prod | U24: =M7*2 -> 120000 | V24: =U24/U25 -> 9.2307692
B25: 23 | C25: Elasticsearch Master & Data | D25: ELK Stack | E25: Community | F25: DC2 | G25: 3 | H25: 8 | I25: 32 | J25: 300 | K25: =H25*G25 -> 24 | L25: =I25*G25 -> 96 | M25: =J25*G25 -> 900 | N25: =K25*#REF! -> #REF! | O25: =M25*#REF! -> #REF! | R25: =SUM(N25:Q25) -> #REF! | T25: Strg DB PT | U25: =M32 -> 13000 | V25: 1
B26: 24 | C26: Kibana Logstash | D26: ELK Stack | E26: Community | F26: DC2 | G26: 1 | H26: 8 | I26: 16 | J26: 300 | K26: =H26*G26 -> 8 | L26: =I26*G26 -> 16 | M26: =J26*G26 -> 300 | N26: =K26*#REF! -> #REF! | O26: =M26*#REF! -> #REF! | R26: =SUM(N26:Q26) -> #REF!
B28: 25 | C28: Redhat OCP Master | D28: Container Platform | E28: Enterprise | F28: PT | G28: 3 | H28: 8 | I28: 32 | J28: 150 | K28: =H28*G28 -> 24 | L28: =I28*G28 -> 96 | M28: =J28*G28 -> 450 | N28: =K28*#REF! -> #REF! | O28: =M28*#REF! -> #REF! | R28: =SUM(N28:Q28) -> #REF!
B29: 26 | C29: Redhat OCP Infra Router | D29: Container Platform | E29: Enterprise | F29: PT | G29: 5 | H29: 8 | I29: 32 | J29: 150 | K29: =H29*G29 -> 40 | L29: =I29*G29 -> 160 | M29: =J29*G29 -> 750 | N29: =K29*#REF! -> #REF! | O29: =M29*#REF! -> #REF! | R29: =SUM(N29:Q29) -> #REF! | T29: Strg Prod | U29: =SUM(M3:M26) -> 137048 | V29: =U29/U30 -> 6.367218
B30: 27 | C30: Redhat OCP Worker (Baremetal) | D30: Container Platform | E30: Enterprise | F30: PT | G30: 1 | H30: 64 | I30: 1024 | J30: 1024 | K30: =H30*G30 -> 64 | L30: =I30*G30 -> 1024 | M30: =J30*G30 -> 1024 | N30: 0 | O30: 0 | Q30: =G30*#REF! -> #REF! | R30: =SUM(N30:Q30) -> #REF! | T30: Strg PT | U30: =SUM(M28:M39) -> 21524 | V30: =1 -> 1
B31: 28 | C31: Bastion & HA Proxy | D31: Bastion | E31: Enterprise | F31: PT | G31: 1 | H31: 4 | I31: 8 | J31: 100 | K31: =H31*G31 -> 4 | L31: =I31*G31 -> 8 | M31: =J31*G31 -> 100 | N31: =K31*#REF! -> #REF! | O31: =M31*#REF! -> #REF! | R31: =SUM(N31:Q31) -> #REF!
B32: 29 | C32: Oracle Database RAC (Baremetal) | D32: Database | E32: Enterprise | F32: PT | G32: 2 | H32: 64 | I32: 1024 | J32: 13000 | K32: =H32*G32 -> 128 | L32: =I32*G32 -> 2048 | M32: 13000 | N32: 0 | O32: =M32*#REF! -> #REF! | Q32: =G32*#REF! -> #REF! | R32: =SUM(N32:Q32) -> #REF! | T32: Memoru Prod | U32: =SUM(L3:L26) -> 7248 | V32: =U32/U33 -> 1.9738562
B33: 30 | C33: Nginx Community | D33: Application Gateway | E33: Community | F33: PT | G33: 2 | H33: 8 | I33: 16 | J33: 200 | K33: =H33*G33 -> 16 | L33: =I33*G33 -> 32 | M33: =J33*G33 -> 400 | N33: =K33*#REF! -> #REF! | O33: =M33*#REF! -> #REF! | R33: =SUM(N33:Q33) -> #REF! | T33: Memory PT | U33: =SUM(L28:L40) -> 3672 | V33: 1
B34: 31 | C34: Redis Enterprise | D34: Cache Database | E34: Enterprise | F34: PT | G34: 3 | H34: 8 | I34: 16 | J34: 200 | K34: =H34*G34 -> 24 | L34: =I34*G34 -> 48 | M34: =J34*G34 -> 600 | N34: =K34*#REF! -> #REF! | O34: =M34*#REF! -> #REF! | R34: =SUM(N34:Q34) -> #REF!
B35: 32 | C35: Confluent Kafka Community App Log (Non Financial) | D35: Kafka Broker & Zookeeper | E35: Community | F35: PT | G35: 3 | H35: 8 | I35: 16 | J35: 1000 | K35: =H35*G35 -> 24 | L35: =I35*G35 -> 48 | M35: =J35*G35 -> 3000 | N35: =K35*#REF! -> #REF! | O35: =M35*#REF! -> #REF! | R35: =SUM(N35:Q35) -> #REF! | T35: CPU Prod
B36: 33 | C36: Batch Control M | D36: Batch Server | E36: Enterprise | F36: PT | G36: 1 | H36: 8 | I36: 16 | J36: 500 | K36: =H36*G36 -> 8 | L36: =I36*G36 -> 16 | M36: =J36*G36 -> 500 | N36: =K36*#REF! -> #REF! | O36: =M36*#REF! -> #REF! | R36: =SUM(N36:Q36) -> #REF! | T36: CPU Dev
B37: 34 | C37: MinIO | D37: Object Storage | E37: Enterprise | F37: PT | G37: 1 | H37: 16 | I37: 32 | J37: 500 | K37: =H37*G37 -> 16 | L37: =I37*G37 -> 32 | M37: =J37*G37 -> 500 | N37: =K37*#REF! -> #REF! | O37: =M37*#REF! -> #REF! | R37: =SUM(N37:Q37) -> #REF!
B38: 35 | C38: Elasticsearch Master & Data | D38: ELK Stack | E38: Community | F38: PT | G38: 3 | H38: 8 | I38: 32 | J38: 300 | K38: =H38*G38 -> 24 | L38: =I38*G38 -> 96 | M38: =J38*G38 -> 900 | N38: =K38*#REF! -> #REF! | O38: =M38*#REF! -> #REF! | R38: =SUM(N38:Q38) -> #REF!
B39: 36 | C39: Kibana Logstash | D39: ELK Stack | E39: Community | F39: PT | G39: 1 | H39: 8 | I39: 16 | J39: 300 | K39: =H39*G39 -> 8 | L39: =I39*G39 -> 16 | M39: =J39*G39 -> 300 | N39: =K39*#REF! -> #REF! | O39: =M39*#REF! -> #REF! | R39: =SUM(N39:Q39) -> #REF!
B40: 37 | C40: Wiremock | D40: Wiremock | E40: Community | F40: PT | G40: 2 | H40: 8 | I40: 24 | J40: 128 | K40: =H40*G40 -> 16 | L40: =I40*G40 -> 48 | M40: =J40*G40 -> 256 | N40: =K40*#REF! -> #REF! | O40: =M40*#REF! -> #REF! | R40: =SUM(N40:Q40) -> #REF!
B42: 38 | C42: Oracle Database (VM) | D42: Database | E42: Enterprise | F42: DEV & UAT | G42: 1 | H42: 16 | I42: 32 | J42: =2500 -> 2500 | K42: =H42*G42 -> 16 | L42: 64 | M42: =J42*G42 -> 2500 | N42: =K42*#REF! -> #REF! | O42: =M42*#REF! -> #REF! | R42: =SUM(N42:Q42) -> #REF!
...

Sheet FS Opsi Oracle Single T3
B1: Summary Hardware
B2: No | C2: Group | D2: Description | E2: Edition | F2: Environment | G2: # of VM | H2: CPU | I2: Memory | J2: Storage | K2: Total CPU | L2: Total Memory | M2: Total Storage | N2: Pricing CPU | O2: Pricing Storage | P2: Pricing Rubrik / NBU | Q2: Pricing Baremetal | R2: Total
B3: 1 | C3: Redhat OCP Master | D3: Container Platform | E3: Enterprise | F3: DC1 | G3: 3 | H3: 8 | I3: 32 | J3: 150 | K3: =H3*G3 -> 24 | L3: =I3*G3 -> 96 | M3: =J3*G3 -> 450 | N3: =K3*#REF! -> #REF! | O3: =M3*#REF! -> #REF! | P3: 0 | R3: =SUM(N3:Q3) -> #REF!
B4: 2 | C4: Redhat OCP Infra Router | D4: Container Platform | E4: Enterprise | F4: DC1 | G4: 5 | H4: 8 | I4: 32 | J4: 150 | K4: =H4*G4 -> 40 | L4: =I4*G4 -> 160 | M4: =J4*G4 -> 750 | N4: =K4*#REF! -> #REF! | O4: =M4*#REF! -> #REF! | P4: 0 | R4: =SUM(N4:Q4) -> #REF!
B5: 3 | C5: Redhat OCP Worker (Baremetal) | D5: Container Platform | E5: Enterprise | F5: DC1 | G5: 1 | H5: 64 | I5: 1024 | J5: 1024 | K5: =H5*G5 -> 64 | L5: =I5*G5 -> 1024 | M5: =J5*G5 -> 1024 | N5: 0 | O5: 0 | P5: 0 | Q5: =G5*#REF! -> #REF! | R5: =SUM(N5:Q5) -> #REF!
B6: 4 | C6: Bastion & HA Proxy | D6: Bastion | E6: Enterprise | F6: DC1 | G6: 1 | H6: 4 | I6: 8 | J6: 100 | K6: =H6*G6 -> 4 | L6: =I6*G6 -> 8 | M6: =J6*G6 -> 100 | N6: =K6*#REF! -> #REF! | O6: =M6*#REF! -> #REF! | P6: 0 | R6: =SUM(N6:Q6) -> #REF!
B7: 5 | C7: Oracle Database RAC (Baremetal) | D7: Database | E7: Enterprise | F7: DC1 | G7: 1 | H7: 64 | I7: 1024 | J7: 60000 | K7: =H7*G7 -> 64 | L7: =I7*G7 -> 1024 | M7: =J7 -> 60000 | N7: 0 | O7: =M7*#REF! -> #REF! | P7: =M7*50%*80%*#REF! -> #REF! | Q7: =G7*#REF! -> #REF! | R7: =SUM(N7:Q7) -> #REF!
B8: 6 | C8: Nginx Community | D8: Application Gateway | E8: Community | F8: DC1 | G8: 2 | H8: 8 | I8: 16 | J8: 200 | K8: =H8*G8 -> 16 | L8: =I8*G8 -> 32 | M8: =G8*J8 -> 400 | N8: =K8*#REF! -> #REF! | O8: =M8*#REF! -> #REF! | R8: =SUM(N8:Q8) -> #REF!
B9: 7 | C9: Redis Enterprise | D9: Cache Database | E9: Enterprise | F9: DC1 | G9: 3 | H9: 8 | I9: 16 | J9: 200 | K9: =H9*G9 -> 24 | L9: =I9*G9 -> 48 | M9: =G9*J9 -> 600 | N9: =K9*#REF! -> #REF! | O9: =M9*#REF! -> #REF! | R9: =SUM(N9:Q9) -> #REF!
B10: 8 | C10: Confluent Kafka Community App Log (Non Financial) | D10: Kafka Broker & Zookeeper | E10: Community | F10: DC1 | G10: 3 | H10: 8 | I10: 16 | J10: 1000 | K10: =H10*G10 -> 24 | L10: =I10*G10 -> 48 | M10: =G10*J10 -> 3000 | N10: =K10*#REF! -> #REF! | O10: =M10*#REF! -> #REF! | R10: =SUM(N10:Q10) -> #REF!
B11: 9 | C11: Batch Control M | D11: Batch Server | E11: Enterprise | F11: DC1 | G11: 1 | H11: 8 | I11: 16 | J11: 500 | K11: =H11*G11 -> 8 | L11: =I11*G11 -> 16 | M11: =G11*J11 -> 500 | N11: =K11*#REF! -> #REF! | O11: =M11*#REF! -> #REF! | R11: =SUM(N11:Q11) -> #REF!
B12: 10 | C12: MinIO | D12: Object Storage | E12: Community | F12: DC1 | G12: 1 | H12: 16 | I12: 32 | J12: 500 | K12: =H12*G12 -> 16 | L12: =I12*G12 -> 32 | M12: =G12*J12 -> 500 | N12: =K12*#REF! -> #REF! | O12: =M12*#REF! -> #REF! | R12: =SUM(N12:Q12) -> #REF!
