Workbook

Sheet Cover & HLD Architecture
B2: BASELINE ARSITEKTUR & SIZING INFRASTRUKTUR IT
B3: STANDAR KOMPARASI: TIER MODERATE (IHSP/RMT) VS TIER CRITICAL (LIVIN' MERCHANT)
B4: Dokumen Acuan: EA Forum C STM2601010 (IHSP), Capacity Plan RMT, & EA Forum B DRB2502010 (Livin' Merchant)
C6: Nama Dokumen | D6: Baseline Sizing Infrastruktur & Technology Stack | F6: Target Environment | G6: Production (DC Wisdan & DRC Rempoa), PT, DEV & UAT
C7: Sistem Acuan Moderate | D7: Integrated HC Suite Platform (IHSP) & RM Tools (RMT) | F7: Sistem Acuan Critical | G7: Livin' Merchant (LM) - Merchant App 2026 Release 6
C8: Arsitektur Database | D8: Moderate: Single Node VM Data Guard (Tanpa RAC) | F8: Database Critical | G8: Critical: Oracle RAC Bare Metal + 5.5 TB ASM SAN Storage
C9: Klasifikasi EA Forum | D9: Moderate: Forum C (STM2601010) | Critical: Forum B | F9: Pola Logging & Monitoring | G9: Moderate: ELK Co-located / Shared | Critical: ELK Dedicated Cluster (Logstash Terpisah)
B11: RINGKASAN SIZING & ALOKASI RESOURCE (BASELINE)
C12: Tier Moderate Compute | E12: Tier Moderate Storage | G12: Tier Critical Compute | I12: Tier Critical Storage
C13: 14 VM Nodes | E13: 4.500 GB (4.5 TB) | G13: 28 Dedicated Nodes | I13: 24.500 GB (24.5 TB)
C14: 112 vCPU | 256 GB RAM (IHSP/RMT) | E14: SAN Tier 2 LUN Virtual Disk | G14: 384 vCPU | 4.8 TB RAM (incl 4 BM) | I14: High-Perf ASM SAN Tier 2
B16: MATRIKS KOMPARASI KOMPONEN TEKNOLOGI (MODERATE VS CRITICAL)
B17: No | C17: Layer Arsitektur | D17: Komponen Sistem | E17: Spesifikasi Tier Moderate (IHSP/RMT) | F17: Spesifikasi Tier Critical (Livin' Merchant) | G17: Ketentuan Lisensi & Catatan EA
B18: 1 | C18: Web Ingress | D18: NGINX Web Server | E18: 2 VM per site (8 vCPU / 16GB / 100-200GB) | F18: 2 VM per site (8-16 vCPU / 16-32GB / 100-200GB) | G18: Moderate: NGINX Community (Open Source). Critical: NGINX Plus Enterprise Subscription (Kontrak F5: TIF.DDL/GH.9076/2025).
B19: 2 | C19: App Container | D19: Red Hat OCP Worker | E19: 1 Worker VM per site (64 vCPU / 1024GB / 300GB) | F19: 2 Dedicated Bare Metal Workers per site (64 vCPU / 1024GB / 300GB) | G19: Moderate: OCP Core Subscription. Critical: Red Hat OpenShift Platform Plus Bare Metal Node Premium (Kontrak TIF.DDL/GH.1993/2025).
B20: 3 | C20: Container Router | D20: OCP Infra Router & Bastion | E20: 3 Infra Router (8/32/150) + 1 Bastion HA (4/8/100) | F20: Dedicated High-Throughput Ingress Router Pods | G20: Included dalam langganan Red Hat OpenShift Container Platform.
B21: 4 | C21: Core Database | D21: Database Engine (Oracle) | E21: Single Node VM Data Guard (16 vCPU / 32GB / 1000GB) | F21: Oracle RAC Bare Metal (2x 64-Core BM per site + Active Data Guard) | G21: Moderate: Oracle DB Enterprise (tanpa RAC Option untuk efisiensi lisensi core). Critical: Oracle RAC Bare Metal (High TPS & zero data loss, Kontrak TIF.DDL/SCD.3585/2025).
B22: 5 | C22: Database Storage | D22: Oracle ASM Shared Storage | E22: Storage SAN Tier 2 Virtual LUN (1.0 TB - 1.5 TB) | F22: Storage SAN Tier 2 High-Performance ASM (5.5 TB: Reco 500GB, Data 5TB) | G22: Diskgroup tablespace data dan Fast Recovery Area (FRA) berbasis ASM striping.
B23: 6 | C23: Distributed Cache | D23: Redis Caching Cluster | E23: 1-3 VM (8 vCPU / 16GB / 200GB) | F23: 3 VM Multi-Shard (8 vCPU / 32GB / 200GB) | G23: Moderate: Redis Community (Open Source). Critical: Redis Enterprise Software Subscription (Kontrak TIF.DDL/GH.9080/2024).
B24: 7 | C24: Cache Sentinel | D24: Redis Sentinel Quorum | E24: Co-located / 1 Standalone VM | F24: Dedicated Sentinel Quorum Arbiter antar-DC (Wisdan & Rempoa) | G24: Arbiter quorum untuk deteksi failover otomatis dan promosi master Redis cross-DC.
B25: 8 | C25: Message Bus | D25: Confluent / Apache Kafka | E25: 3 VM (16 vCPU / 64GB / 600GB atau 8/16/1000GB) | F25: Dedicated Cluster 7 VM: 3 ZK (4/32/100) + 3 Broker (16/32/1000) + 1 C3 (8/16/100) | G25: Moderate: Kafka Community (Shared broker cluster). Critical: Confluent Kafka Enterprise Subscription (Kontrak TIF.DDL/GH.9075/2024).
B26: 9 | C26: Log Analytics | D26: Elasticsearch Data Cluster | E26: Combined dengan Logstash (1 Logstash + 3 Master/Data 8/32/500) | F26: Dedicated Cluster 8 VM: 3 Master (8/32/50), 2 Hot Data (16/32/1900), 1 Warm, 2 Coordinator | G26: Moderate: OpenSearch / Elasticsearch Basic. Critical: Elasticsearch Platinum (Kontrak TIF.DDL/GH.9074/2024). Pemisahan node data hot & master untuk kestabilan heap JVM.
B27: 10 | C27: Log Shipper | D27: Logstash Pipeline Shipper | E27: Combined / Co-located pada server logging | F27: Dedicated 2 VM Logstash Shipper (PVLMEL01/02 8 vCPU / 32GB / 100GB) | G27: Moderate: Co-located. Critical: Wajib dipisah ke server tersendiri agar proses parsing Grok tidak membebani query indexing Elasticsearch.
B28: 11 | C28: Log Dashboard | D28: Kibana Observability | E28: Shared Dashboard Portal | F28: Terintegrasi pada Coordinator Node (PVLMEC01/02 4 vCPU / 32GB / 50GB) | G28: Visualisasi audit log transaksi, tracing performa APM, dan dashboard operasional.
B29: 12 | C29: Document Storage | D29: Object Storage / SFTP / RDM | E29: VM SFTP Server (8/16/1500) / MinIO S3 Gateway | F29: Storage Gateway SAN RDM (8/16/365) / Dell ECS Object Storage | G29: Media penyimpanan arsip dokumen, file transaksi QRIS, invoice merchant, dan pertukaran file MFT.
B30: 13 | C30: Batch Engine | D30: BMC Control-M / OCP Cron | E30: Scheduled CronJob pada worker container OCP | F30: Dedicated VM Agent BMC Control-M (PVLMBC01 / RVLMBC01 4/8/100) | G30: Moderate: Native OCP CronJob. Critical: BMC Control-M Enterprise untuk otomasi settlement transaksi end-of-day.

Sheet Template Tech Stack
B1: BASELINE TECHNOLOGY STACK & SIZING PATTERN (BANK MANDIRI)
B2: Standar Arsitektur: Tier Moderate (IHSP & RMT) vs Tier Critical (Livin' Merchant)
B3: No | C3: Layer Arsitektur | D3: Komponen / Software | E3: TIER MODERATE (IHSP & RMT) | H3: TIER CRITICAL (LIVIN' MERCHANT) | K3: KATEGORI LISENSI | M3: Catatan Arsitektur & Justifikasi Sizing
E4: Node Alokasi | F4: Tipe Compute | G4: Spec per Node (CPU/RAM/Disk) | H4: Node Alokasi | I4: Tipe Compute | J4: Spec per Node (CPU/RAM/Disk) | K4: Free / Community | L4: Enterprise
B5: 1 | C5: Web Ingress | D5: NGINX Web Server | E5: 2N (2 Nodes) | F5: Virtual Machine (VM) | G5: 8 vCPU / 16GB RAM / 100-200GB Disk | H5: 2N (2 Nodes) | I5: Virtual Machine (VM) | J5: 8-16 vCPU / 16-32GB RAM / 100-200GB Disk | K5: NGINX Community (com) | L5: NGINX Plus (F5 Enterprise) | M5: Moderate: NGINX VM 8/16/100 (IHSP) / 8/16/200 (RMT). Critical: NGINX Plus VM 8-16 vCPU / 16-32 GB (Kontrak F5: TIF.DDL/GH.9076/2025).
B6: 2 | C6: App Container | D6: Red Hat OCP Worker | E6: 1W (1 Worker) | F6: Shared / VM Worker | G6: 64 vCPU / 1024GB RAM / 300GB Disk | H6: 2N (2 Nodes) | I6: Dedicated Baremetal Worker | J6: 2x 64 vCPU / 1024GB RAM / 300GB Disk | K6: OKD (Non-Prod) | L6: RH OCP Platform Plus BM Premium | M6: Moderate: 1 OCP Worker VM (64/1024/300) per DC. Critical: 2 Dedicated Bare Metal Workers per DC (PPWRKR01/02 & RPWRKR01/02, Kontrak Red Hat: TIF.DDL/GH.1993/2025).
B7: 3 | C7: Container Router | D7: OCP Infra Router & Bastion | E7: 3 Infra + 1 Bastion | F7: VM Router / HA Proxy | G7: 8 vCPU / 32GB RAM / 150GB Disk | H7: Dedicated Router Pods | I7: High-Throughput Router Pods | J7: 8 vCPU / 32GB RAM / 150GB Disk | K7: Included in OCP | L7: Included in OCP Platform Plus | M7: Moderate: 3 Master (8/32/150) + 3 Infra Router (8/32/150) + 1 Bastion (4/8/100). Critical: Dedicated high-throughput router pods cross-DC.
B8: 4 | C8: Core Database | D8: Database Engine (Oracle) | E8: Single Node, VM | F8: Virtual Machine (VM) | G8: 16 vCPU / 32GB RAM / 1000GB Disk | H8: RAC, BM (Baremetal) | I8: Physical Baremetal + ASM | J8: 2x 64 vCPU BM Server / 1024GB RAM | K8: PostgreSQL / MySQL Com | L8: Oracle DB Enterprise (RAC + ADG) | M8: Moderate: Single Node VM + Data Guard (16/32/1000) tanpa RAC Option untuk efisiensi lisensi core. Critical: Oracle RAC Bare Metal 2x64-Core (High TPS & Zero Data Loss, Kontrak: TIF.DDL/SCD.3585/2025).
B9: 5 | C9: Database Storage | D9: Oracle ASM Shared SAN | E9: SAN Virtual Disk LUN | F9: Storage SAN Tier 2 | G9: 1.000 GB - 1.500 GB SAN LUN | H9: Dedicated ASM SAN Cluster | I9: High-Perf SAN Tier 2 | J9: 5.500 GB (5.5 TB: Reco 500GB, Data 5TB) | K9: SAN LUN Tier 2 | L9: SAN LUN + Oracle ASM | M9: Moderate: SAN Tier 2 Virtual LUN 1.0 - 1.5 TB. Critical: SAN Tier 2 ASM 5.5 TB (Reco 500GB, Data 5000GB) pada node bare metal.
B10: 6 | C10: Distributed Cache | D10: Redis Caching Cluster | E10: 1-3 Nodes | F10: Virtual Machine (VM) | G10: 8 vCPU / 16GB RAM / 200GB Disk | H10: 3 Nodes Multi-Shard | I10: Virtual Machine (VM) | J10: 3x 8 vCPU / 32GB RAM / 200GB Disk | K10: Redis Community (com) | L10: Redis Enterprise Software | M10: Moderate: 1-3 VM Redis Community (8/16/200). Critical: 3 VM Redis Enterprise Multi-Shard (PVLMRD01-03 8/32/200, Kontrak: TIF.DDL/GH.9080/2024).
B11: 7 | C11: Cache Sentinel | D11: Redis Sentinel Quorum | E11: Co-located / Sentinel | F11: Shared VM | G11: 4 vCPU / 8GB RAM / 100GB Disk | H11: Dedicated Sentinel DC2 | I11: Virtual Machine (VM) | J11: 4-8 vCPU / 16GB RAM / 100GB Disk | K11: Redis Community (com) | L11: Redis Enterprise | M11: Moderate: Co-located sentinel. Critical: Dedicated sentinel cross-DC (Wisdan & Rempoa) untuk quorum deteksi failover otomatis.
B12: 8 | C12: Message Bus | D12: Confluent / Apache Kafka | E12: 3 Nodes (Shared/VM) | F12: VM Broker Cluster | G12: 16 vCPU / 64GB / 600GB (IHSP) | H12: Dedicated Cluster (7 Nodes) | I12: ZK + Broker + C3 Cluster | J12: 3 ZK (4/32) + 3 Broker (16/32/1000) + 1 C3 | K12: Apache / Confluent Com | L12: Confluent Kafka Enterprise | M12: Moderate: 3 VM Kafka Community (16/64/600 atau 8/16/1000). Critical: 7 Dedicated VM Confluent Kafka Enterprise (3 ZK + 3 Broker + 1 C3, Kontrak: TIF.DDL/GH.9075/2024).
B13: 9 | C13: Log Analytics | D13: Elasticsearch Analytics Node | E13: Combined dgn Logstash | F13: Shared VM / Combined | G13: 3 Nodes (8 vCPU / 32GB RAM / 500GB) | H13: Dedicated Cluster (8 Nodes) | I13: Master + Hot + Warm + Coord | J13: 3 Master (8/32/50) + 2 Hot (16/32/1900) + Warm + Coord | K13: Elasticsearch / OpenSearch | L13: Elasticsearch Platinum | M13: Moderate: ELK combined (1 Logstash + 3 Master/Data 8/32/500). Critical: Dedicated 8 VM (3 Master 8/32/50, 2 Hot Data 16/32/1900, 1 Warm, 2 Coord, Kontrak: TIF.DDL/GH.9074/2024).
B14: 10 | C14: Log Shipper | D14: Logstash Pipeline Shipper | E14: Combined / Co-located | F14: Shared VM | G14: 1 Node (8 vCPU / 32GB RAM / 100GB) | H14: Dedicated Shipper Nodes | I14: Virtual Machine (VM) | J14: 2 Nodes (8 vCPU / 32GB RAM / 100GB) | K14: Logstash Open Source | L14: Elastic Platinum | M14: Moderate: Combined pada node ELK. Critical: Dedicated 2 VM Logstash Shipper (PVLMEL01/02 8/32/100 di DC & RVLMEL01/02 di DRC) terpisah dari data cluster demi kestabilan heap JVM.
B15: 11 | C15: Log Dashboard | D15: Kibana Observability Portal | E15: Shared Portal | F15: Shared VM Portal | G15: Resource sharing on ELK | H15: Dedicated Portal Nodes | I15: Virtual Machine (VM) | J15: 2 Nodes (4 vCPU / 32GB RAM / 50GB) | K15: Kibana Community (com) | L15: Elastic Platinum | M15: Moderate: Shared portal. Critical: Terintegrasi pada coordinator node PVLMEC01/02 (4/32/50 di DC & RVLMEC01/02 di DRC).
B16: 12 | C16: Document Storage | D16: SFTP / Object Storage / RDM | E16: SFTP Server VM | F16: Virtual Machine (VM) | G16: 8 vCPU / 16GB RAM / 1.500GB Disk | H16: SAN RDM / Dell ECS S3 | I16: Dedicated SAN LUN | J16: 8 vCPU / 16GB RAM / 365GB Disk | K16: MinIO / OpenSFTP (com) | L16: Dell ECS / SAN Enterprise | M16: Moderate: VM SFTP Server (8/16/1500) untuk pertukaran file benefit MFT. Critical: Storage Gateway SAN RDM / Dell ECS S3 untuk arsip transaksi & bukti settlement.
B17: 13 | C17: Batch Engine | D17: BMC Control-M / OCP Cron | E17: Scheduled Cron on OCP | F17: Shared OCP Worker | G17: Resource sharing on OCP Pods | H17: Dedicated Batch Control-M | I17: Virtual Machine (VM) | J17: 4 vCPU / 8GB RAM / 100GB Disk | K17: OCP Native Batch Cron | L17: BMC Control-M Enterprise | M17: Moderate: Scheduled CronJob pada worker container OCP. Critical: Dedicated VM Agent BMC Control-M (PVLMBC01 / RVLMBC01 4/8/100) untuk batch settlement end-of-day.
B19: CATATAN ARSITEKTUR & ACUAN RESMI EA FORUM
B20: TIER MODERATE: IHSP (STM2601010) & RMT (RM TOOLS SATU R1) | H20: TIER CRITICAL: LIVIN' MERCHANT (DRB2502010 R6 SESI 2)
B21: IHSP (Integrated HC Suite Platform) | D21: Acuan Dokumen: EA Forum C STM2601010 R1.1. Sizing per site: NGINX 8/16/100, OCP Master 8/32/150, Infra Router 8/32/150, 1 OCP Worker 64/1024/300, DB VM 16/32/1000, Kafka 16/64/600, SFTP 8/16/1500, ELK 8/32/500. | H21: Livin' Merchant (Release 6 Sesi 2) | J21: Acuan Dokumen: EA Forum B DRB2502010 R6 Sesi 2. Klasifikasi: Very Critical (Forum B) melayani transaksi merchant nasional 24/7 (SLA 99.99%). Wajib 2 Dedicated OCP Bare Metal Workers (64/1024/300) dan Oracle RAC Bare Metal 64-Core (ASM SAN 5.5 TB).
B22: RMT (RM Tools SATU R1) & Pola Migrasi RAC | D22: Acuan Dokumen: Capacity Plan RM Tools SATU R1 & evaluasi migrasi database (20260824). NGINX 8/16/200, Redis 8/16/200, Kafka 8/16/1000. Database dialihkan dari RAC ke Single Node Data Guard (Wisdan Primary, Rempoa Standby) untuk optimasi lisensi core. | H22: Pemisahan Node Logging (ELK & Logstash) | J22: Acuan Server List LM (Tabel 108): Elasticsearch dipisah menjadi Master (PVLMEM01-03 8/32/50), Hot Data (PVLMDH01-02 16/32/1900), Warm Data (PVLMDW01), Coordinator (PVLMEC01-02), dan Logstash Shipper (PVLMEL01-02 8/32/100) di server tersendiri demi stabilitas indexing.
B23: Ketentuan Arsitektur Tier Moderate | D23: Kategori EA Forum: Forum C. Target SLA Ketersediaan: 99.5% - 99.9% (RTO < 2 jam, RPO < 15 menit). Seluruh server berbasis Virtual Machine (VM). Database Single Node Data Guard. Server logging (ELK & Logstash) diperbolehkan shared/co-located. | H23: Lisensi Resmi Enterprise di Livin' Merchant | J23: NGINX Plus (TIF.DDL/GH.9076/2025), Red Hat OCP Platform Plus Bare Metal (TIF.DDL/GH.1993/2025), Oracle RAC Enterprise (TIF.DDL/SCD.3585/2025), Confluent Kafka (TIF.DDL/GH.9075/2024), Elasticsearch Platinum (TIF.DDL/GH.9074/2024), Redis Enterprise (TIF.DDL/GH.9080/2024).

Sheet Sizing Tier Moderate (IHSP RMT)
B1: BILL OF QUANTITY (BOQ) & SIZING - TIER MODERATE (IHSP & RMT)
B2: No | C2: Group | D2: Description | E2: Edition | F2: Environment | G2: # of VM | H2: CPU | I2: Memory | J2: Storage | K2: Total CPU | L2: Total Memory | M2: Total Storage | N2: Pricing CPU | O2: Pricing Storage | P2: Pricing Backup (NBU) | Q2: Pricing Baremetal | R2: Total (IDR / Thn)
B3: 1 | C3: Web Ingress (NGINX) | D3: NGINX Ingress Node 1 (8/16/100) | E3: Community | F3: DC1 | G3: 1 | H3: 8 | I3: 16 | J3: 100 | K3: =G3*H3 | L3: =G3*I3 | M3: =G3*J3 | N3: =K3*Pricing!$D$3 | O3: =M3*Pricing!$D$5 | P3: =M3*0.5*0.8*Pricing!$D$8 | Q3: 0 | R3: =N3+O3+P3+Q3
B4: 2 | C4: Web Ingress (NGINX) | D4: NGINX Ingress Node 2 (8/16/100) | E4: Community | F4: DC1 | G4: 1 | H4: 8 | I4: 16 | J4: 100 | K4: =G4*H4 | L4: =G4*I4 | M4: =G4*J4 | N4: =K4*Pricing!$D$3 | O4: =M4*Pricing!$D$5 | P4: =M4*0.5*0.8*Pricing!$D$8 | Q4: 0 | R4: =N4+O4+P4+Q4
B5: 3 | C5: App Platform (OCP) | D5: Red Hat OCP Worker 1W (64/1024/300) | E5: Enterprise | F5: DC1 | G5: 1 | H5: 64 | I5: 1024 | J5: 300 | K5: =G5*H5 | L5: =G5*I5 | M5: =G5*J5 | N5: =K5*Pricing!$D$3 | O5: =M5*Pricing!$D$5 | P5: =M5*0.5*0.8*Pricing!$D$8 | Q5: 0 | R5: =N5+O5+P5+Q5
B6: 4 | C6: OCP Infra & Master | D6: OCP Master & Infra Router Quorum | E6: Enterprise | F6: DC1 | G6: 1 | H6: 8 | I6: 32 | J6: 150 | K6: =G6*H6 | L6: =G6*I6 | M6: =G6*J6 | N6: =K6*Pricing!$D$3 | O6: =M6*Pricing!$D$5 | P6: =M6*0.5*0.8*Pricing!$D$8 | Q6: 0 | R6: =N6+O6+P6+Q6
B7: 5 | C7: Database (Oracle VM) | D7: Oracle DB Single Node VM Primary (16/32/1000) | E7: Enterprise | F7: DC1 | G7: 1 | H7: 16 | I7: 32 | J7: 1000 | K7: =G7*H7 | L7: =G7*I7 | M7: =G7*J7 | N7: =K7*Pricing!$D$3 | O7: =M7*Pricing!$D$5 | P7: =M7*0.5*0.8*Pricing!$D$8 | Q7: 0 | R7: =N7+O7+P7+Q7
B8: 6 | C8: Message Bus (Kafka) | D8: Confluent Kafka Shared Broker (16/64/600) | E8: Community | F8: DC1 | G8: 3 | H8: 16 | I8: 64 | J8: 600 | K8: =G8*H8 | L8: =G8*I8 | M8: =G8*J8 | N8: =K8*Pricing!$D$3 | O8: =M8*Pricing!$D$5 | P8: =M8*0.5*0.8*Pricing!$D$8 | Q8: 0 | R8: =N8+O8+P8+Q8
B9: 7 | C9: Caching (Redis) | D9: Redis Cache Standalone (8/16/200) | E9: Community | F9: DC1 | G9: 1 | H9: 8 | I9: 16 | J9: 200 | K9: =G9*H9 | L9: =G9*I9 | M9: =G9*J9 | N9: =K9*Pricing!$D$3 | O9: =M9*Pricing!$D$5 | P9: =M9*0.5*0.8*Pricing!$D$8 | Q9: 0 | R9: =N9+O9+P9+Q9
B10: 8 | C10: Storage MFT (SFTP) | D10: SFTP Gateway Server (8/16/1500) | E10: Community | F10: DC1 | G10: 1 | H10: 8 | I10: 16 | J10: 1500 | K10: =G10*H10 | L10: =G10*I10 | M10: =G10*J10 | N10: =K10*Pricing!$D$3 | O10: =M10*Pricing!$D$5 | P10: =M10*0.5*0.8*Pricing!$D$8 | Q10: 0 | R10: =N10+O10+P10+Q10
B11: 9 | C11: Log Shipper (Logstash) | D11: ELK Server - Logstash Shipper (8/32/100) | E11: Community | F11: DC1 | G11: 1 | H11: 8 | I11: 32 | J11: 100 | K11: =G11*H11 | L11: =G11*I11 | M11: =G11*J11 | N11: =K11*Pricing!$D$3 | O11: =M11*Pricing!$D$5 | P11: =M11*0.5*0.8*Pricing!$D$8 | Q11: 0 | R11: =N11+O11+P11+Q11
B12: 10 | C12: Log Data (Elasticsearch) | D12: ELK Server - Master & Data (8/32/500) | E12: Community | F12: DC1 | G12: 3 | H12: 8 | I12: 32 | J12: 500 | K12: =G12*H12 | L12: =G12*I12 | M12: =G12*J12 | N12: =K12*Pricing!$D$3 | O12: =M12*Pricing!$D$5 | P12: =M12*0.5*0.8*Pricing!$D$8 | Q12: 0 | R12: =N12+O12+P12+Q12
B13: 11 | C13: Monitoring (Prometheus) | D13: Monitoring Server Grafana & Prometheus (16/32/300) | E13: Community | F13: DC1 | G13: 1 | H13: 16 | I13: 32 | J13: 300 | K13: =G13*H13 | L13: =G13*I13 | M13: =G13*J13 | N13: =K13*Pricing!$D$3 | O13: =M13*Pricing!$D$5 | P13: =M13*0.5*0.8*Pricing!$D$8 | Q13: 0 | R13: =N13+O13+P13+Q13
B15: 12 | C15: Web Ingress (NGINX) | D15: NGINX Ingress Node 1 DRC (8/16/100) | E15: Community | F15: DC2 | G15: 1 | H15: 8 | I15: 16 | J15: 100 | K15: =G15*H15 | L15: =G15*I15 | M15: =G15*J15 | N15: =K15*Pricing!$D$3 | O15: =M15*Pricing!$D$5 | P15: =M15*0.5*0.8*Pricing!$D$8 | Q15: 0 | R15: =N15+O15+P15+Q15
... B22: 19 | C22: Log Data (Elasticsearch) | D22: ELK Server Standby Replica (8/32/500) | E22: Community | F22: DC2 | G22: 3 | H22: 8 | I22: 32 | J22: 500 | K22: =G22*H22 | L22: =G22*I22 | M22: =G22*J22 | N22: =K22*Pricing!$D$3 | O22: =M22*Pricing!$D$5 | P22: =M22*0.5*0.8*Pricing!$D$8 | Q22: 0 | R22: =N22+O22+P22+Q22
B24: 20 | C24: Web Ingress (NGINX PT) | D24: NGINX Ingress PT (8/16/100) | E24: Community | F24: DEV | G24: 2 | H24: 8 | I24: 16 | J24: 100 | K24: =G24*H24 | L24: =G24*I24 | M24: =G24*J24 | N24: =K24*Pricing!$D$4 | O24: =M24*Pricing!$D$7 | P24: =M24*0.5*0.8*Pricing!$D$8 | Q24: 0 | R24: =N24+O24+P24+Q24
B25: 21 | C25: App Platform (OCP PT) | D25: OCP Worker PT Pods (64/1024/300) | E25: Enterprise | F25: DEV | G25: 1 | H25: 64 | I25: 1024 | J25: 300 | K25: =G25*H25 | L25: =G25*I25 | M25: =G25*J25 | N25: =K25*Pricing!$D$4 | O25: =M25*Pricing!$D$7 | P25: =M25*0.5*0.8*Pricing!$D$8 | Q25: 0 | R25: =N25+O25+P25+Q25
B26: 22 | C26: Database (Oracle PT) | D26: Oracle DB PT Instance (16/32/1000) | E26: Enterprise | F26: DEV | G26: 1 | H26: 16 | I26: 32 | J26: 1000 | K26: =G26*H26 | L26: =G26*I26 | M26: =G26*J26 | N26: =K26*Pricing!$D$4 | O26: =M26*Pricing!$D$7 | P26: =M26*0.5*0.8*Pricing!$D$8 | Q26: 0 | R26: =N26+O26+P26+Q26
B27: 23 | C27: Message Bus (Kafka PT) | D27: Kafka Broker PT (16/64/600) | E27: Community | F27: DEV | G27: 3 | H27: 16 | I27: 64 | J27: 600 | K27: =G27*H27 | L27: =G27*I27 | M27: =G27*J27 | N27: =K27*Pricing!$D$4 | O27: =M27*Pricing!$D$7 | P27: =M27*0.5*0.8*Pricing!$D$8 | Q27: 0 | R27: =N27+O27+P27+Q27
B28: 24 | C28: Caching (Redis PT) | D28: Redis Cache PT (8/16/200) | E28: Community | F28: DEV | G28: 1 | H28: 8 | I28: 16 | J28: 200 | K28: =G28*H28 | L28: =G28*I28 | M28: =G28*J28 | N28: =K28*Pricing!$D$4 | O28: =M28*Pricing!$D$7 | P28: =M28*0.5*0.8*Pricing!$D$8 | Q28: 0 | R28: =N28+O28+P28+Q28
B29: 25 | C29: App Platform (OCP DEV) | D29: OCP Worker DEV Pods (64/1024/300) | E29: Enterprise | F29: DEV | G29: 1 | H29: 64 | I29: 1024 | J29: 300 | K29: =G29*H29 | L29: =G29*I29 | M29: =G29*J29 | N29: =K29*Pricing!$D$4 | O29: =M29*Pricing!$D$7 | P29: =M29*0.5*0.8*Pricing!$D$8 | Q29: 0 | R29: =N29+O29+P29+Q29
B30: TOTAL BIAYA INFRASTRUKTUR / TAHUN | G30: =SUM(G3:G29) | K30: =SUM(K3:K29) | L30: =SUM(L3:L29) | M30: =SUM(M3:M29) | N30: =SUM(N3:N29) | O30: =SUM(O3:O29) | P30: =SUM(P3:P29) | Q30: =SUM(Q3:Q29) | R30: =SUM(R3:R29)
B32: Summary Hardware Prod | G32: Matriks Alokasi Resource Data Center
B33: No | C33: Item | D33: Price | G33: DC / Environment | H33: CPU (vCPU) | I33: RAM (GB) | J33: Storage (GB)
B34: 1 | C34: Web Ingress (NGINX) | D34: =SUM(R3:R4)+SUM(R15:R16) | G34: DC1 (Wisdan - Active) | H34: =SUM(K3:K13) | I34: =SUM(L3:L13) | J34: =SUM(M3:M13)
B35: 2 | C35: App Platform (OCP Worker & Master) | D35: =SUM(R5:R6)+R17 | G35: DC2 (Rempoa - Standby) | H35: =SUM(K15:K22) | I35: =SUM(L15:L22) | J35: =SUM(M15:M22)
B36: 3 | C36: Core Database (Oracle VM Single Node) | D36: =R7+R18 | G36: PT (Performance Test) | H36: =SUM(K24:K28) | I36: =SUM(L24:L28) | J36: =SUM(M24:M28)
B37: 4 | C37: Message Bus (Kafka Cluster) | D37: =R8+R19 | G37: DEV & UAT (Testing) | H37: =K29 | I37: =L29 | J37: =M29
B38: 5 | C38: Caching (Redis Standalone) | D38: =R9+R20
B39: 6 | C39: Storage MFT (SFTP Gateway) | D39: =R10+R21
B40: 7 | C40: Logging & Shipper (ELK Cluster) | D40: =SUM(R11:R12)+R22
B41: 8 | C41: Monitoring Server (Grafana / Prometheus) | D41: =R13
C42: Total | D42: =SUM(D34:D41)
B44: Summary Hardware PT
B45: No | C45: Item | D45: Price
B46: 1 | C46: Web Ingress (NGINX PT) | D46: =R24
B47: 2 | C47: App Platform (OCP PT) | D47: =R25
B48: 3 | C48: Database (Oracle PT) | D48: =R26
B49: 4 | C49: Message Bus (Kafka PT) | D49: =R27
B50: 5 | C50: Caching (Redis PT) | D50: =R28
...

Sheet Sizing Tier Critical (LM)
B1: BILL OF QUANTITY (BOQ) & SIZING - TIER CRITICAL (LIVIN' MERCHANT)
B2: No | C2: Group | D2: Description | E2: Edition | F2: Environment | G2: # of VM | H2: CPU | I2: Memory | J2: Storage | K2: Total CPU | L2: Total Memory | M2: Total Storage | N2: Pricing CPU | O2: Pricing Storage | P2: Pricing Backup (NBU) | Q2: Pricing Baremetal | R2: Total (IDR / Thn)
B3: 1 | C3: Web Ingress (Nginx Plus) | D3: PVLMNG01ABD24LP - Nginx Plus Gateway | E3: Enterprise | F3: DC1 | G3: 1 | H3: 8 | I3: 16 | J3: 100 | K3: =G3*H3 | L3: =G3*I3 | M3: =G3*J3 | N3: =K3*Pricing!$D$3 | O3: =M3*Pricing!$D$5 | P3: =M3*0.5*0.8*Pricing!$D$8 | Q3: 0 | R3: =N3+O3+P3+Q3
B4: 2 | C4: Web Ingress (Nginx Plus) | D4: PVLMNG02ABD24LP - Nginx Plus Gateway | E4: Enterprise | F4: DC1 | G4: 1 | H4: 8 | I4: 16 | J4: 100 | K4: =G4*H4 | L4: =G4*I4 | M4: =G4*J4 | N4: =K4*Pricing!$D$3 | O4: =M4*Pricing!$D$5 | P4: =M4*0.5*0.8*Pricing!$D$8 | Q4: 0 | R4: =N4+O4+P4+Q4
B5: 3 | C5: OCP Worker (Baremetal) | D5: PPWRKR01LMC25LP - OCP BM Worker Node 1 | E5: Enterprise | F5: DC1 | G5: 1 | H5: 64 | I5: 1024 | J5: 300 | K5: =G5*H5 | L5: =G5*I5 | M5: =G5*J5 | N5: =K5*Pricing!$D$3 | O5: =M5*Pricing!$D$5 | P5: =M5*0.5*0.8*Pricing!$D$8 | Q5: =G5*Pricing!$D$10 | R5: =N5+O5+P5+Q5
B6: 4 | C6: OCP Worker (Baremetal) | D6: PPWRKR02LMC25LP - OCP BM Worker Node 2 | E6: Enterprise | F6: DC1 | G6: 1 | H6: 64 | I6: 1024 | J6: 300 | K6: =G6*H6 | L6: =G6*I6 | M6: =G6*J6 | N6: =K6*Pricing!$D$3 | O6: =M6*Pricing!$D$5 | P6: =M6*0.5*0.8*Pricing!$D$8 | Q6: =G6*Pricing!$D$10 | R6: =N6+O6+P6+Q6
B7: 5 | C7: Oracle DB RAC 1 (BM) | D7: PPLMDB1DRX25LP - Oracle RAC BM Node 1 | E7: Enterprise | F7: DC1 | G7: 1 | H7: 64 | I7: 1024 | J7: 500 | K7: =G7*H7 | L7: =G7*I7 | M7: =G7*J7 | N7: =K7*Pricing!$D$3 | O7: =M7*Pricing!$D$5 | P7: =M7*0.5*0.8*Pricing!$D$8 | Q7: =G7*Pricing!$D$10 | R7: =N7+O7+P7+Q7
B8: 6 | C8: Oracle DB RAC 2 (BM) | D8: PPLMDB2DRX25LP - Oracle RAC BM Node 2 | E8: Enterprise | F8: DC1 | G8: 1 | H8: 64 | I8: 1024 | J8: 500 | K8: =G8*H8 | L8: =G8*I8 | M8: =G8*J8 | N8: =K8*Pricing!$D$3 | O8: =M8*Pricing!$D$5 | P8: =M8*0.5*0.8*Pricing!$D$8 | Q8: =G8*Pricing!$D$10 | R8: =N8+O8+P8+Q8
B9: 7 | C9: Oracle DB ASM SAN Storage | D9: Oracle ASM SAN Storage Tier 2 (Data 5.0 TB) | E9: Enterprise | F9: DC1 | G9: 1 | H9: 0 | I9: 0 | J9: 5000 | K9: =G9*H9 | L9: =G9*I9 | M9: =G9*J9 | N9: =K9*Pricing!$D$3 | O9: =M9*Pricing!$D$5 | P9: =M9*0.5*0.8*Pricing!$D$8 | Q9: 0 | R9: =N9+O9+P9+Q9
B10: 8 | C10: Redis Enterprise Shard 1 | D10: PVLMRD01ABD24LP - Redis Enterprise Node 1 | E10: Enterprise | F10: DC1 | G10: 1 | H10: 8 | I10: 32 | J10: 200 | K10: =G10*H10 | L10: =G10*I10 | M10: =G10*J10 | N10: =K10*Pricing!$D$3 | O10: =M10*Pricing!$D$5 | P10: =M10*0.5*0.8*Pricing!$D$8 | Q10: 0 | R10: =N10+O10+P10+Q10
B11: 9 | C11: Redis Enterprise Shard 2 | D11: PVLMRD02ABD24LP - Redis Enterprise Node 2 | E11: Enterprise | F11: DC1 | G11: 1 | H11: 8 | I11: 32 | J11: 200 | K11: =G11*H11 | L11: =G11*I11 | M11: =G11*J11 | N11: =K11*Pricing!$D$3 | O11: =M11*Pricing!$D$5 | P11: =M11*0.5*0.8*Pricing!$D$8 | Q11: 0 | R11: =N11+O11+P11+Q11
B12: 10 | C12: Redis Enterprise Shard 3 | D12: PVLMRD03ABD24LP - Redis Enterprise Node 3 | E12: Enterprise | F12: DC1 | G12: 1 | H12: 8 | I12: 32 | J12: 200 | K12: =G12*H12 | L12: =G12*I12 | M12: =G12*J12 | N12: =K12*Pricing!$D$3 | O12: =M12*Pricing!$D$5 | P12: =M12*0.5*0.8*Pricing!$D$8 | Q12: 0 | R12: =N12+O12+P12+Q12
B13: 11 | C13: Kafka Zookeeper Cluster | D13: PVLMZK01-03 - Confluent Kafka Zookeeper | E13: Enterprise | F13: DC1 | G13: 3 | H13: 4 | I13: 32 | J13: 100 | K13: =G13*H13 | L13: =G13*I13 | M13: =G13*J13 | N13: =K13*Pricing!$D$3 | O13: =M13*Pricing!$D$5 | P13: =M13*0.5*0.8*Pricing!$D$8 | Q13: 0 | R13: =N13+O13+P13+Q13
B14: 12 | C14: Kafka Broker Cluster | D14: PVLMKB01-03 - Confluent Kafka Broker | E14: Enterprise | F14: DC1 | G14: 3 | H14: 16 | I14: 32 | J14: 1000 | K14: =G14*H14 | L14: =G14*I14 | M14: =G14*J14 | N14: =K14*Pricing!$D$3 | O14: =M14*Pricing!$D$5 | P14: =M14*0.5*0.8*Pricing!$D$8 | Q14: 0 | R14: =N14+O14+P14+Q14
B15: 13 | C15: Kafka Connect C3 | D15: PVLMKC01ABD24LP - Confluent Control Center | E15: Enterprise | F15: DC1 | G15: 1 | H15: 8 | I15: 16 | J15: 100 | K15: =G15*H15 | L15: =G15*I15 | M15: =G15*J15 | N15: =K15*Pricing!$D$3 | O15: =M15*Pricing!$D$5 | P15: =M15*0.5*0.8*Pricing!$D$8 | Q15: 0 | R15: =N15+O15+P15+Q15
B16: 14 | C16: Elasticsearch Master | D16: PVLMEM01-03 - Elasticsearch Master Node | E16: Enterprise | F16: DC1 | G16: 3 | H16: 8 | I16: 32 | J16: 50 | K16: =G16*H16 | L16: =G16*I16 | M16: =G16*J16 | N16: =K16*Pricing!$D$3 | O16: =M16*Pricing!$D$5 | P16: =M16*0.5*0.8*Pricing!$D$8 | Q16: 0 | R16: =N16+O16+P16+Q16
B17: 15 | C17: Elasticsearch Data Hot | D17: PVLMDH01-02 - Elasticsearch Data Hot Node | E17: Enterprise | F17: DC1 | G17: 2 | H17: 16 | I17: 32 | J17: 1900 | K17: =G17*H17 | L17: =G17*I17 | M17: =G17*J17 | N17: =K17*Pricing!$D$3 | O17: =M17*Pricing!$D$5 | P17: =M17*0.5*0.8*Pricing!$D$8 | Q17: 0 | R17: =N17+O17+P17+Q17
B18: 16 | C18: Elasticsearch Data Warm | D18: PVLMDW01 - Elasticsearch Data Warm Node | E18: Enterprise | F18: DC1 | G18: 1 | H18: 16 | I18: 32 | J18: 1900 | K18: =G18*H18 | L18: =G18*I18 | M18: =G18*J18 | N18: =K18*Pricing!$D$3 | O18: =M18*Pricing!$D$5 | P18: =M18*0.5*0.8*Pricing!$D$8 | Q18: 0 | R18: =N18+O18+P18+Q18
B19: 17 | C19: Elasticsearch Coordinator | D19: PVLMEC01-02 - Elasticsearch Coordinator Node | E19: Enterprise | F19: DC1 | G19: 2 | H19: 4 | I19: 32 | J19: 50 | K19: =G19*H19 | L19: =G19*I19 | M19: =G19*J19 | N19: =K19*Pricing!$D$3 | O19: =M19*Pricing!$D$5 | P19: =M19*0.5*0.8*Pricing!$D$8 | Q19: 0 | R19: =N19+O19+P19+Q19
B20: 18 | C20: Logstash Shipper | D20: PVLMEL01-02 - Logstash Shipper Node | E20: Enterprise | F20: DC1 | G20: 2 | H20: 8 | I20: 32 | J20: 100 | K20: =G20*H20 | L20: =G20*I20 | M20: =G20*J20 | N20: =K20*Pricing!$D$3 | O20: =M20*Pricing!$D$5 | P20: =M20*0.5*0.8*Pricing!$D$8 | Q20: 0 | R20: =N20+O20+P20+Q20
... B24: 21 | C24: Web Ingress (Nginx Plus) | D24: RVLMNG02ABD24LP - Nginx Plus Gateway DRC | E24: Enterprise | F24: DC2 | G24: 1 | H24: 8 | I24: 16 | J24: 100 | K24: =G24*H24 | L24: =G24*I24 | M24: =G24*J24 | N24: =K24*Pricing!$D$3 | O24: =M24*Pricing!$D$5 | P24: =M24*0.5*0.8*Pricing!$D$8 | Q24: 0 | R24: =N24+O24+P24+Q24
B25: 22 | C25: OCP Worker (Baremetal) | D25: RPWRKR01LMC25LP - OCP BM Worker Node 1 DRC | E25: Enterprise | F25: DC2 | G25: 1 | H25: 64 | I25: 1024 | J25: 300 | K25: =G25*H25 | L25: =G25*I25 | M25: =G25*J25 | N25: =K25*Pricing!$D$3 | O25: =M25*Pricing!$D$5 | P25: =M25*0.5*0.8*Pricing!$D$8 | Q25: =G25*Pricing!$D$10 | R25: =N25+O25+P25+Q25
B26: 23 | C26: OCP Worker (Baremetal) | D26: RPWRKR02LMC25LP - OCP BM Worker Node 2 DRC | E26: Enterprise | F26: DC2 | G26: 1 | H26: 64 | I26: 1024 | J26: 300 | K26: =G26*H26 | L26: =G26*I26 | M26: =G26*J26 | N26: =K26*Pricing!$D$3 | O26: =M26*Pricing!$D$5 | P26: =M26*0.5*0.8*Pricing!$D$8 | Q26: =G26*Pricing!$D$10 | R26: =N26+O26+P26+Q26
B27: 24 | C27: Oracle DB RAC 1 (BM) | D27: RPLMDB1DRX25LP - Oracle RAC BM Node 1 DRC | E27: Enterprise | F27: DC2 | G27: 1 | H27: 64 | I27: 1024 | J27: 500 | K27: =G27*H27 | L27: =G27*I27 | M27: =G27*J27 | N27: =K27*Pricing!$D$3 | O27: =M27*Pricing!$D$5 | P27: =M27*0.5*0.8*Pricing!$D$8 | Q27: =G27*Pricing!$D$10 | R27: =N27+O27+P27+Q27
B28: 25 | C28: Oracle DB RAC 2 (BM) | D28: RPLMDB2DRX25LP - Oracle RAC BM Node 2 DRC | E28: Enterprise | F28: DC2 | G28: 1 | H28: 64 | I28: 1024 | J28: 500 | K28: =G28*H28 | L28: =G28*I28 | M28: =G28*J28 | N28: =K28*Pricing!$D$3 | O28: =M28*Pricing!$D$5 | P28: =M28*0.5*0.8*Pricing!$D$8 | Q28: =G28*Pricing!$D$10 | R28: =N28+O28+P28+Q28
B29: 26 | C29: Oracle DB ASM SAN Storage | D29: Oracle ASM SAN Storage Tier 2 DRC (Data 5.0 TB) | E29: Enterprise | F29: DC2 | G29: 1 | H29: 0 | I29: 0 | J29: 5000 | K29: =G29*H29 | L29: =G29*I29 | M29: =G29*J29 | N29: =K29*Pricing!$D$3 | O29: =M29*Pricing!$D$5 | P29: =M29*0.5*0.8*Pricing!$D$8 | Q29: 0 | R29: =N29+O29+P29+Q29
B30: 27 | C30: Redis Enterprise Shard | D30: RVLMRD01-03 - Redis Enterprise Replica DRC | E30: Enterprise | F30: DC2 | G30: 3 | H30: 8 | I30: 32 | J30: 200 | K30: =G30*H30 | L30: =G30*I30 | M30: =G30*J30 | N30: =K30*Pricing!$D$3 | O30: =M30*Pricing!$D$5 | P30: =M30*0.5*0.8*Pricing!$D$8 | Q30: 0 | R30: =N30+O30+P30+Q30
B31: 28 | C31: Kafka Zookeeper Cluster | D31: RVLMZK01-03 - Confluent Kafka Zookeeper DRC | E31: Enterprise | F31: DC2 | G31: 3 | H31: 4 | I31: 32 | J31: 100 | K31: =G31*H31 | L31: =G31*I31 | M31: =G31*J31 | N31: =K31*Pricing!$D$3 | O31: =M31*Pricing!$D$5 | P31: =M31*0.5*0.8*Pricing!$D$8 | Q31: 0 | R31: =N31+O31+P31+Q31
B32: 29 | C32: Kafka Broker Cluster | D32: RVLMKB01-03 - Confluent Kafka Broker DRC | E32: Enterprise | F32: DC2 | G32: 3 | H32: 16 | I32: 32 | J32: 1000 | K32: =G32*H32 | L32: =G32*I32 | M32: =G32*J32 | N32: =K32*Pricing!$D$3 | O32: =M32*Pricing!$D$5 | P32: =M32*0.5*0.8*Pricing!$D$8 | Q32: 0 | R32: =N32+O32+P32+Q32
B33: 30 | C33: Elasticsearch Master | D33: RVLMEM01-03 - Elasticsearch Master Node DRC | E33: Enterprise | F33: DC2 | G33: 3 | H33: 8 | I33: 32 | J33: 50 | K33: =G33*H33 | L33: =G33*I33 | M33: =G33*J33 | N33: =K33*Pricing!$D$3 | O33: =M33*Pricing!$D$5 | P33: =M33*0.5*0.8*Pricing!$D$8 | Q33: 0 | R33: =N33+O33+P33+Q33
B34: 31 | C34: Elasticsearch Data Hot | D34: RVLMDH01-02 - Elasticsearch Data Hot Node DRC | E34: Enterprise | F34: DC2 | G34: 2 | H34: 16 | I34: 32 | J34: 1900 | K34: =G34*H34 | L34: =G34*I34 | M34: =G34*J34 | N34: =K34*Pricing!$D$3 | O34: =M34*Pricing!$D$5 | P34: =M34*0.5*0.8*Pricing!$D$8 | Q34: 0 | R34: =N34+O34+P34+Q34
B35: 32 | C35: Elasticsearch Data Warm | D35: RVLMDW01 - Elasticsearch Data Warm Node DRC | E35: Enterprise | F35: DC2 | G35: 1 | H35: 16 | I35: 32 | J35: 1900 | K35: =G35*H35 | L35: =G35*I35 | M35: =G35*J35 | N35: =K35*Pricing!$D$3 | O35: =M35*Pricing!$D$5 | P35: =M35*0.5*0.8*Pricing!$D$8 | Q35: 0 | R35: =N35+O35+P35+Q35
B36: 33 | C36: Logstash Shipper | D36: RVLMEL01-02 - Logstash Shipper Node DRC | E36: Enterprise | F36: DC2 | G36: 2 | H36: 8 | I36: 32 | J36: 100 | K36: =G36*H36 | L36: =G36*I36 | M36: =G36*J36 | N36: =K36*Pricing!$D$3 | O36: =M36*Pricing!$D$5 | P36: =M36*0.5*0.8*Pricing!$D$8 | Q36: 0 | R36: =N36+O36+P36+Q36
B38: 34 | C38: Web Ingress (Nginx PT) | D38: Nginx Plus PT Gateway | E38: Enterprise | F38: DEV | G38: 2 | H38: 8 | I38: 16 | J38: 100 | K38: =G38*H38 | L38: =G38*I38 | M38: =G38*J38 | N38: =K38*Pricing!$D$4 | O38: =M38*Pricing!$D$7 | P38: =M38*0.5*0.8*Pricing!$D$8 | Q38: 0 | R38: =N38+O38+P38+Q38
B39: 35 | C39: OCP Worker (PT Pod) | D39: Red Hat OCP Worker PT Pods | E39: Enterprise | F39: DEV | G39: 1 | H39: 16 | I39: 32 | J39: 200 | K39: =G39*H39 | L39: =G39*I39 | M39: =G39*J39 | N39: =K39*Pricing!$D$4 | O39: =M39*Pricing!$D$7 | P39: =M39*0.5*0.8*Pricing!$D$8 | Q39: 0 | R39: =N39+O39+P39+Q39
B40: 36 | C40: Oracle DB Standalone (PT) | D40: Oracle DB PT Standalone Instance (VM) | E40: Enterprise | F40: DEV | G40: 1 | H40: 16 | I40: 32 | J40: 1000 | K40: =G40*H40 | L40: =G40*I40 | M40: =G40*J40 | N40: =K40*Pricing!$D$4 | O40: =M40*Pricing!$D$7 | P40: =M40*0.5*0.8*Pricing!$D$8 | Q40: 0 | R40: =N40+O40+P40+Q40
B41: 37 | C41: Kafka Broker Non-Prod | D41: Kafka Broker Non-Prod Cluster | E41: Enterprise | F41: DEV | G41: 3 | H41: 4 | I41: 16 | J41: 300 | K41: =G41*H41 | L41: =G41*I41 | M41: =G41*J41 | N41: =K41*Pricing!$D$4 | O41: =M41*Pricing!$D$7 | P41: =M41*0.5*0.8*Pricing!$D$8 | Q41: 0 | R41: =N41+O41+P41+Q41
B42: 38 | C42: Elasticsearch Non-Prod | D42: Elasticsearch PT Cluster Node | E42: Enterprise | F42: DEV | G42: 2 | H42: 8 | I42: 16 | J42: 200 | K42: =G42*H42 | L42: =G42*I42 | M42: =G42*J42 | N42: =K42*Pricing!$D$4 | O42: =M42*Pricing!$D$7 | P42: =M42*0.5*0.8*Pricing!$D$8 | Q42: 0 | R42: =N42+O42+P42+Q42
B43: 39 | C43: Logstash Non-Prod | D43: Logstash PT Shipper Node | E43: Enterprise | F43: DEV | G43: 1 | H43: 4 | I43: 8 | J43: 100 | K43: =G43*H43 | L43: =G43*I43 | M43: =G43*J43 | N43: =K43*Pricing!$D$4 | O43: =M43*Pricing!$D$7 | P43: =M43*0.5*0.8*Pricing!$D$8 | Q43: 0 | R43: =N43+O43+P43+Q43
B44: TOTAL BIAYA INFRASTRUKTUR / TAHUN | G44: =SUM(G3:G43) | K44: =SUM(K3:K43) | L44: =SUM(L3:L43) | M44: =SUM(M3:M43) | N44: =SUM(N3:N43) | O44: =SUM(O3:O43) | P44: =SUM(P3:P43) | Q44: =SUM(Q3:Q43) | R44: =SUM(R3:R43)
...

Sheet Pricing
A1: Hardware
A2: No | B2: Item | C2: Env | D2: Price
A3: 1 | B3: vCPU | C3: Production | D3: =7500000*110%
A4: 2 | B4: vCPU | C4: Dev | D4: =6500000*110%
A5: 3 | B5: Storage Tier 2 | C5: Production | D5: 33000
A6: 4 | B6: Storage Tier 3 | C6: Production | D6: 48000
A7: 5 | B7: Storage Dev | C7: Dev | D7: 28600
A8: 6 | B8: Netbackup | C8: Production | D8: 27000
A9: 7 | B9: Rubrik | C9: Production | D9: 35000
A10: 8 | B10: Baremetal | C10: Production | D10: 794000000
A11: 9 | B11: Baremetal | C11: Dev | D11: 794000000
A14: License
A15: No | B15: Item | C15: Env | D15: Price
A16: 1 | B16: NGINX | C16: Production
A17: 2 | B17: NGINX | C17: Dev
A18: 3 | B18: Openshift | C18: Production | D18: 240000000
A19: 4 | B19: Openshift | C19: Dev | D19: 134000000
A20: 5 | B20: Redis | C20: Production | D20: 125000000
A21: 6 | B21: Redis | C21: Dev | D21: 75000000
A22: 7 | B22: Confluent Kafka | C22: Production
A23: 8 | B23: Confluent Kafka | C23: Dev
A24: Note : Perlu confirm ke STA, untuk harga terbaru

Sheet Formula & Guidelines
B1: KAMUS PERHITUNGAN SIZING & FORMULA BIAYA INFRASTRUKTUR
B2: No | C2: Parameter Sizing | D2: Formula Perhitungan | E2: Logika Kalkulasi | F2: Ketentuan Arsitektur & Best Practice
B3: 1 | C3: Total Compute vCPU | D3: # of VM * vCPU | E3: Perkalian jumlah VM dengan alokasi vCPU per node. | F3: Moderate NGINX: 2 VM x 8 vCPU = 16 vCPU. Critical NGINX: 2 VM x 8-16 vCPU.
B4: 2 | C4: Total Memory RAM | D4: # of VM * RAM (GB) | E4: Perkalian jumlah VM dengan alokasi Memory (GB) per node. | F4: Moderate NGINX: 2 x 16GB = 32GB RAM. Critical NGINX: 2 x 16-32GB RAM.
B5: 3 | C5: Total Storage Disk | D5: # of VM * Disk (GB) | E5: Perkalian jumlah VM dengan kapasitas storage disk (GB) per node. | F5: Standar root OS & file logging: 100GB - 200GB per VM.
B6: 4 | C6: Pemisahan Logstash & Elasticsearch | D6: Node Segregation (Tier Critical) | E6: Logstash shipper dipisahkan ke server tersendiri di luar cluster Elasticsearch. | F6: Tier Critical memisahkan Logstash (PVLMEL) dari Elasticsearch Master (PVLMEM) dan Hot Data (PVLMDH) agar resource parsing Grok tidak memicu Out of Memory (OOM) pada heap JVM Elasticsearch.
B7: 5 | C7: Biaya vCPU Tahunan | D7: Total vCPU * Tarif vCPU | E7: Total vCPU dikalikan tarif standar tahunan (Production atau Dev). | F7: Mengacu sheet Pricing: Production Rp 8.250.000/vCPU/thn (=7.500.000*110%), Dev Rp 7.150.000/vCPU/thn (=6.500.000*110%).
B8: 6 | C8: Biaya Storage Tahunan | D8: Total Storage * Tarif Storage | E8: Total GB dikalikan tarif Storage SAN Tier 2 tahunan. | F8: Mengacu sheet Pricing: Production Tier 2 Rp 33.000/GB/thn, Dev Rp 28.600/GB/thn.
B9: 7 | C9: Biaya Backup Netbackup | D9: Storage * 50% * 80% * Tarif NBU | E9: Storage dikalikan 50% (asumsi data aktif), 80% (deduplikasi), dan tarif Rp 27.000/GB. | F9: Formula standar Bank Mandiri untuk proteksi dan pencadangan data berkala.
B10: 8 | C10: Biaya Pengadaan Bare Metal | D10: # Unit BM * Tarif Server | E10: Jumlah unit physical server dikalikan tarif pengadaan Rp 794.000.000. | F10: Digunakan khusus Tier Critical (Oracle RAC Bare Metal & Dedicated OCP Worker BM).
B11: 9 | C11: Pola Database: Single Node vs RAC | D11: Pola Arsitektur Database | E11: Moderate: Single Node VM Data Guard | Critical: Oracle RAC Bare Metal | F11: Tier Moderate mengoptimalkan biaya lisensi core database melalui Single Node Data Guard; Tier Critical wajib Oracle RAC Bare Metal untuk menangani beban transaksi tinggi dengan zero downtime failover.
